Workbook

Sheet GIAM
A2: TẬP ĐOÀN HÓA CHẤT VIỆT NAM | H2: CỘNG HÒA XÃ HỘI CHỦ NGHĨA VIỆT NAM
A3: CTY CP PHÂN BÓN & HÓA CHẤT CẦN THƠ | H3: Độc lập - Tự do - Hạnh phúc
H4: Cần Thơ, ngày tháng năm 2026
A6: BÁO CÁO GIẢM NHÂN SỰ TRONG CÁC THÁNG NĂM 2026
A8: THÁNG | B8: STT | C8: MS | D8: HỌ VÀ TÊN | E8: NGÀY SINH | F8: NGÀY VÀO LÀM | G8: SỐ QUYÉT ĐỊNH | H8: NGÀY KÝ QUYẾT ĐỊNH | I8: ĐƠN VỊ CÔNG TÁC | J8: GHI CHÚ
A9: 01
B10: 1 | C10: 1 | D10: Nguyễn Văn Trí | I10: XNPBHC | J10: ST
B11: 2 | C11: 2 | D11: Đào Duy Khanh | I11: XNPBHC
B12: 3 | C12: 3 | D12: Bùi Đặng Anh Thùy | I12: Giám sát
B13: 4 | C13: 4 | D13: Nguyễn Hàm Chất | I13: Giám sát
A15: 3 | B15: 1 | C15: 5 | D15: Lại Văn Minh | F15: 45807 | G15: 23/QĐ-PBHC | H15: 46082 | I15: XNPBHC
B16: 2 | C16: 6 | D16: Nguyễn Hữu Thạnh | F16: 45461 | G16: 24/QĐ-PBHC | H16: 46083 | I16: XNPBHC
B17: 3 | C17: 7 | D17: Lê Võ Nhật Khoa | F17: 45962 | G17: 25/QĐ-PBHC | H17: 46083 | I17: KHVT
B18: 4 | C18: 8 | D18: Huỳnh Minh Thư | F18: 45903 | G18: 26/QĐ-PBHC | H18: 46083 | I18: XNPBHC
B19: 5 | C19: 9 | D19: Đặng Bảo | F19: 46172 | G19: 27/QĐ-PBHC | H19: 46083 | I19: XNPBHC
B20: 6 | C20: 10 | D20: Huỳnh Văn Bình | F20: 46023 | G20: 28/QĐ-PBHC | H20: 46083 | I20: XNPBHC
B21: 7 | C21: 11 | D21: Hoàng Văn Tư | G21: 30/QĐ-PBHC | H21: 46083 | I21: XNPBHC | J21: ST
B22: 8 | C22: 12 | D22: Quách Trung Hậu | G22: 31/QĐ-PBHC | H22: 46091 | I22: XNPBHC | J22: ST
B23: 9 | C23: 13 | D23: Nguyễn Hoàng Anh | G23: 32/QĐ-PBHC | H23: 46091 | I23: XNPBHC
B24: 10 | C24: 14 | D24: Trần Văn Tươi
A26: 4 | B26: 1 | C26: 15 | D26: Lâm Văn Đời | G26: 33/QĐ-PBHC | H26: 46096 | I26: XNPBHC
B27: 2 | C27: 16 | D27: Trần Thị Bảo Hân | G27: 34/QĐ-PBHC | H27: 46097 | I27: XNPBHC
B28: 3 | C28: 17 | D28: Lê Chí Cường | G28: 35/QĐ-PBHC | H28: 46122 | I28: XNPBHC
B29: 4 | C29: 18 | D29: Nguyễn Thiện Hoàng | G29: 36/QĐ-PBHC | H29: 46122 | I29: XNPBHC
B30: 5 | C30: 19 | D30: Trần Văn De | G30: 44/QĐ-PBHC | H30: 46112 | I30: XNPBHC
B31: 6 | C31: 20 | D31: Lê Thanh Tùng | G31: 46/QĐ-PBHC | H31: 46125 | I31: XNPBHC
A33: 5 | B33: 1 | C33: 21 | D33: Nguyễn Thị Búp | G33: 43/QĐ-PBHC | H33: 46146 | I33: Giám sát
B34: 2 | C34: 22 | D34: Lâm Duy | G34: 41/QĐ-PBHC | H34: 46154 | I34: XNPBHC
B35: 3 | C35: 23 | D35: Phan Văn Nhẫn | G35: 48/QĐ-PBHC | H35: 46154 | I35: XNPBHC
B36: 4 | C36: 24 | D36: Lê Minh Thảo | G36: 47/QĐ-PBHC | H36: 46148 | I36: XNPBHC
B37: 5 | C37: 25 | D37: Nguyễn Văn Đông | G37: 49/QĐ-PBHC | H37: 46141 | I37: XNPBHC
B38: 6 | C38: 26 | D38: Nguyễn Kiến Văn | G38: 45/QĐ-PBHC | H38: 46119 | I38: XNPBHC
B39: 7 | C39: 27 | D39: Lê Minh Thuận | G39: 73/QĐ-PBHC | H39: 46154 | I39: XNPBHC
B40: 8 | C40: 28 | D40: Lê Văn Thêm | G40: 72/QĐ-PBHC | H40: 46153 | I40: XNPBHC
A41: 6
B42: 1 | C42: 29 | D42: Nguyễn Toàn Thái | G42: 42//QĐ-PBHC | H42: 46160 | I42: KTCĐ
B43: 2 | C43: 30 | D43: Nguyễn Công Phương | G43: 42//QĐ-PBHC | H43: 46185 | I43: KTCĐ
B44: 3 | C44: 31 | D44: Hoàng Mạnh Hùng | G44: 66//QĐ-PBHC | H44: 46187 | I44: KTCĐ
A46: 7 | B46: 1 | D46: Nguyễn Hứa Kim Thảo | G46: 67//QĐ-PBHC | H46: 46193 | I46: PKD
D47: Hồ Xuân Việt | H47: 46204 | I47: Kho
...

Sheet Sheet8
A1: A268 | B1: 9213003755 | C1: Nguyễn Công Huân | D1: =VLOOKUP(A1,#REF!,2,0) -> #REF! | E1: 1
A2: A035 | B2: 5496032611 | C2: Nguyễn Nam Bình | D2: =VLOOKUP(A2,#REF!,2,0) -> #REF! | E2: 2
A3: A279 | B3: 9212004554 | C3: Nguyễn Thanh Duy | D3: =VLOOKUP(A3,#REF!,2,0) -> #REF! | E3: 3
A4: A255 | B4: 9212004139 | C4: Trầm Trung Bích Thảo | D4: =VLOOKUP(A4,#REF!,2,0) -> #REF! | E4: 4
A5: A289 | B5: 5499003403 | C5: Hoàng Thị Thanh Mai | D5: =VLOOKUP(A5,#REF!,2,0) -> #REF! | E5: 5
A6: A215 | B6: 9208007865 | C6: Nguyễn Thị Mỹ Nhiên | D6: =VLOOKUP(A6,#REF!,2,0) -> #REF! | E6: 6
A7: A358 | B7: 9221356007 | C7: Trần Ngọc Bảo Trân | D7: =VLOOKUP(A7,#REF!,2,0) -> #REF! | E7: 7
A8: A369 | B8: 8722989947 | C8: Phan Thanh Trường | D8: =VLOOKUP(A8,#REF!,2,0) -> #REF! | E8: 8
A9: A408 | C9: Trần Chí Đan | D9: =VLOOKUP(A9,#REF!,2,0) -> #REF! | E9: 9
A10: A385 | B10: 8923922038 | C10: Nguyễn Thị Thùy Miên | D10: =VLOOKUP(A10,#REF!,2,0) -> #REF! | E10: 10
A11: A131 | B11: 5402005143 | C11: Trần Ngọc Văn | D11: =VLOOKUP(A11,#REF!,2,0) -> #REF! | E11: 11
A12: C109 | B12: 5496032498 | C12: Lê Huy Minh | D12: =VLOOKUP(A12,#REF!,2,0) -> #REF! | E12: 12
A13: A288 | B13: 9214004739 | C13: Nguyễn Hải Đăng | D13: =VLOOKUP(A13,#REF!,2,0) -> #REF! | E13: 13
A14: A339 | B14: 9216023928 | C14: Lê Minh Toàn | D14: =VLOOKUP(A14,#REF!,2,0) -> #REF! | E14: 14
A15: C562 | B15: 9121911947 | C15: Trần Ngọc Sáng | D15: =VLOOKUP(A15,#REF!,2,0) -> #REF! | E15: 15
A16: A246 | B16: 9210002398 | C16: Trần Minh Giàu | D16: =VLOOKUP(A16,#REF!,2,0) -> #REF! | E16: 16
A17: A025 | B17: 5400002896 | C17: Nguyễn Thị Xuân Diệu | D17: =VLOOKUP(A17,#REF!,2,0) -> #REF! | E17: 17
A18: A327 | B18: 7912294379 | C18: Lê Trung Hiếu | D18: =VLOOKUP(A18,#REF!,2,0) -> #REF! | E18: 18
A19: H062 | B19: 9213008128 | C19: Lê Bằng Thẳng | D19: =VLOOKUP(A19,#REF!,2,0) -> #REF! | E19: 19
A20: A328 | B20: 9216001664 | C20: Huỳnh Phú Nhân | D20: =VLOOKUP(A20,#REF!,2,0) -> #REF! | E20: 20
A21: A367 | B21: 9222306746 | C21: Lương Phú Vinh | D21: =VLOOKUP(A21,#REF!,2,0) -> #REF! | E21: 21
... A25: A403 | B25: 8922957383 | C25: Ngô Văn Tài | D25: =VLOOKUP(A25,#REF!,2,0) -> #REF! | E25: 25
A26: A410 | C26: Huỳnh Văn Linh | D26: =VLOOKUP(A26,#REF!,2,0) -> #REF! | E26: 26
A27: A394 | B27: 9222451383 | C27: Nguyễn Hứa Kim Thảo | D27: =VLOOKUP(A27,#REF!,2,0) -> #REF! | E27: 27
A28: A198 | B28: 5803003379 | C28: Nguyễn Duy Vũ | D28: =VLOOKUP(A28,#REF!,2,0) -> #REF! | E28: 28
A29: A235 | B29: 9210009440 | C29: Phùng Thị Ngọc Thanh | D29: =VLOOKUP(A29,#REF!,2,0) -> #REF! | E29: 29
A30: A245 | B30: 9211007268 | C30: Trần Thị Lệ Thúy | D30: =VLOOKUP(A30,#REF!,2,0) -> #REF! | E30: 30
A31: A362 | B31: 9321603490 | C31: Trần Ngọc Huyền | D31: =VLOOKUP(A31,#REF!,2,0) -> #REF! | E31: 31
A32: A363 | B32: 9221280985 | C32: Nguyễn Thị Hà Thảo | D32: =VLOOKUP(A32,#REF!,2,0) -> #REF! | E32: 32
A33: A379 | B33: 9221417204 | C33: Tiêu Tú Châu | D33: =VLOOKUP(A33,#REF!,2,0) -> #REF! | E33: 33
A34: A406 | B34: 8422038337 | C34: Hà Minh Hiền | D34: =VLOOKUP(A34,#REF!,2,0) -> #REF! | E34: 34
A35: A407 | B35: 9315000203 | C35: Phạm Thị Ngọc Quyên | D35: =VLOOKUP(A35,#REF!,2,0) -> #REF! | E35: 35
A36: A411 | C36: Lê Thị Tố Uyên | D36: =VLOOKUP(A36,#REF!,2,0) -> #REF! | E36: 36
A37: A112 | B37: 5400002895 | C37: Nguyễn Ngọc Diệp Trang | D37: =VLOOKUP(A37,#REF!,2,0) -> #REF! | E37: 37
A38: A395 | B38: 9222599442 | C38: Ngô Thanh Vy | D38: =VLOOKUP(A38,#REF!,2,0) -> #REF! | E38: 38
A39: A391 | B39: 8616014612 | C39: Võ Quỳnh Như | D39: =VLOOKUP(A39,#REF!,2,0) -> #REF! | E39: 39
A40: A154 | B40: 6504006864 | C40: Phan Thị Minh Diễn | D40: =VLOOKUP(A40,#REF!,2,0) -> #REF! | E40: 40
A41: A250 | B41: 5303001410 | C41: Bùi Hữu Thọ | D41: =VLOOKUP(A41,#REF!,2,0) -> #REF! | E41: 41
A42: A381 | B42: 9313001993 | C42: Nguyễn Thị Phương Lan | D42: =VLOOKUP(A42,#REF!,2,0) -> #REF! | E42: 42
A43: A409 | C43: Mã Thị Mỹ Huyền | D43: =VLOOKUP(A43,#REF!,2,0) -> #REF! | E43: 43
...

Sheet Sheet10
A4: A268 | B4: =VLOOKUP(A4,Sheet4!$A$1:$B$300,2,0) -> 9213003755 | C4: Nguyễn Công Huân | D4: Tổng giám đốc
A5: A035 | B5: =VLOOKUP(A5,Sheet4!$A$1:$B$300,2,0) -> 5496032611 | C5: Nguyễn Nam Bình | D5: Phó Tổng giám đốc
A6: A131 | B6: =VLOOKUP(A6,Sheet4!$A$1:$B$300,2,0) -> 5402005143 | C6: Trần Ngọc Văn | D6: Phó Tổng giám đốc
A7: A190 | B7: =VLOOKUP(A7,Sheet4!$A$1:$B$300,2,0) -> 6506006858 | C7: Trần Siêu Đẳng | D7: Phó Tổng giám đốc
A8: A198 | B8: =VLOOKUP(A8,Sheet4!$A$1:$B$300,2,0) -> 5803003379 | C8: Nguyễn Duy Vũ | D8: Kế toán trưởng
A9: A279 | B9: =VLOOKUP(A9,Sheet4!$A$1:$B$300,2,0) -> 9212004554 | C9: Nguyễn Thanh Duy | D9: Trưởng phòng KHVT
A10: A255 | B10: =VLOOKUP(A10,Sheet4!$A$1:$B$300,2,0) -> 9212004139 | C10: Trầm Trung Bích Thảo | D10: Phó phòng KHVT
A11: C109 | B11: =VLOOKUP(A11,Sheet4!$A$1:$B$300,2,0) -> 5496032498 | C11: Lê Huy Minh | D11: Phó phòng KHVT
A12: A339 | B12: =VLOOKUP(A12,Sheet4!$A$1:$B$300,2,0) -> 9216023928 | C12: Lê Minh Toàn | D12: Phó phòng KHVT
A13: A344 | B13: =VLOOKUP(A13,Sheet4!$A$1:$B$300,2,0) -> 9216023766 | C13: Lê Trọng Nhơn | D13: Trưởng phòng Kinh doanh
A14: A328 | B14: =VLOOKUP(A14,Sheet4!$A$1:$B$300,2,0) -> 9216001664 | C14: Huỳnh Phú Nhân | D14: Phó phòng Kinh Doanh
A15: A235 | B15: =VLOOKUP(A15,Sheet4!$A$1:$B$300,2,0) -> 9210009440 | C15: Phùng Thị Ngọc Thanh | D15: Phó phòng kế toán
... A19: D020 | B19: =VLOOKUP(A19,Sheet4!$A$1:$B$300,2,0) -> 5499003400 | C19: Lê Bá Toàn | D19: Trưởng phòng Kỹ thuật
A20: A431 | B20: 8723780534 | C20: Dương Quang Minh | D20: Phó phòng kỹ thuật
A21: A260 | B21: =VLOOKUP(A21,Sheet4!$A$1:$B$300,2,0) -> 9212008058 | C21: Phan Trường Tiền | D21: Trưởng phòng QLCLSP
A22: A171 | B22: =VLOOKUP(A22,Sheet4!$A$1:$B$300,2,0) -> 6506006786 | C22: Đặng Phương Thảo | D22: Phó pòng QLCLSP
A23: A305 | B23: =VLOOKUP(A23,Sheet4!$A$1:$B$300,2,0) -> 9214012340 | C23: Nguyễn Bá Tân | D23: Phó pòng QLCLSP
A24: C235 | B24: =VLOOKUP(A24,Sheet4!$A$1:$B$300,2,0) -> 6506006789 | C24: Nguyễn Hữu Giang | D24: Giám đốc XNPBHC
A25: A304 | B25: =VLOOKUP(A25,Sheet4!$A$1:$B$300,2,0) -> 9214012339 | C25: Giang Minh Tú | D25: Phó giám đốc XNPBHC

Sheet Sheet9

Sheet TĂNG
A2: TẬP ĐOÀN HÓA CHẤT VIỆT NAM | G2: CỘNG HÒA XÃ HỘI CHỦ NGHĨA VIỆT NAM
A3: CTY CP PHÂN BÓN & HÓA CHẤT CẦN THƠ | G3: Độc lập - Tự do - Hạnh phúc
G4: Cần Thơ, ngày tháng năm 2026
A6: BÁO CÁO TĂNG NHÂN SỰ TRONG THÁNG NĂM 2026
A8: THÁNG | B8: STT | C8: MS | D8: HỌ VÀ TÊN | E8: NGÀY SINH | F8: SỐ HĐLĐ | G8: NGÀY KÝ | H8: ĐƠN VỊ CÔNG TÁC | I8: LƯƠNG THAM GIA BHXH | J8: MÃ SỐ BHXH | K8: MÃ SỐ THUẾ TNCN | L8: GHI CHÚ
A13: 1 | B13: 1 | C13: A431 | D13: Dương Quang Minh | L13: 1
B14: 2 | C14: A432 | D14: Nguyễn Tuấn Lộc | L14: 2
B15: 3 | C15: A433 | D15: Võ Hoàng Huy | L15: 3
B16: 4 | C16: D127 | D16: Phạm Lê Như Quỳnh | L16: 4
A18: 3 | C18: A434 | D18: Lê Hoảng Tín | L18: 5
C19: A435 | D19: Nguyễn Trấn Vũ | L19: 6
C20: A436 | D20: Nguyễn Phú Thịnh | L20: 7
C21: A437 | D21: Châu Minh Đức | L21: 8
A22: 5
C23: C720 | D23: Châu Văn Hậu | L23: 9
C24: C721 | D24: Lương Nguyễn Phúc Thịnh | L24: 10
C25: C722 | D25: Lê Hoàng Tâm | L25: 11
C26: C723 | D26: Đào Ngọc Hài | L26: 12
C27: C724 | D27: Phan Văn Mộc | L27: 13
C28: C725 | D28: Nguyễn Ngọc Thành | L28: 14
C29: C726 | D29: Lý Văn Hoàng | L29: 15
C30: C727 | D30: Nguyễn Hoài Nam | L30: 16
C31: C728 | D31: Phan Văn Quí | L31: 17
C32: C729 | D32: Lê Trường Duy | L32: 18
C33: C730 | D33: Trương Quyền Linh | L33: 19
C34: C731 | D34: Phạm Ngọc Trường | L34: 20
... C41: C738 | D41: Nguyễn Văn Trường | L41: 27
A43: 6 | C43: A438 | D43: Trương Bá Duy | L43: 28
C44: A439 | D44: Phan Thị Ngọc Thơ | L44: 29
C45: A440 | D45: Châu Huyền Trân | L45: 30
C46: A441 | D46: Nguyễn Đức Hào | L46: 31
D47: Đoàn Văn Tuấn | L47: 32
D48: Tô Thị Vi Na | L48: 33
D49: Trần Hoàng Huynh | L49: 34
D50: Nguyễn Công Thành | L50: 35
D51: Lê Văn Liên | L51: 41
A52: 7
D53: Hồ Thị Định | L53: 42
D54: Lê Trường Giang | L54: 43
D55: Lê Hoàng Ngân | L55: 44
...

Sheet GS 25
A2: TẬP ĐOÀN HÓA CHẤT VIỆT NAM | G2: CỘNG HÒA XÃ HỘI CHỦ NGHĨA VIỆT NAM
A3: CTY CP PHÂN BÓN & HÓA CHẤT CẦN THƠ | G3: Độc lập - Tự do - Hạnh phúc
G4: Cần Thơ, ngày tháng năm 2025
A6: BÁO CÁO TĂNG NHÂN SỰ TRONG THÁNG NĂM 2025
A8: THÁNG | B8: STT | C8: MS | D8: HỌ VÀ TÊN | E8: NGÀY SINH | F8: Số CCCD | G8: NGÀY cấp | H8: ĐƠN VỊ CÔNG TÁC | I8: LƯƠNG THAM GIA BHXH | J8: MÃ SỐ BHXH | K8: MÃ SỐ THUẾ TNCN | L8: GHI CHÚ
D10: Nguyễn Trí Dũng | E10: 29962 | F10: 60082000576 | G10: 44286 | K10: 8728405013
A53: 4

Sheet Sheet1 (3)
A1: DOANH NGHIỆP……………………….
A2: Mã số thuế: ………………………………………..
A3: Địa chỉ: ………………………………………..
A4: SỔ QUẢN LÝ LAO ĐỘNG
A5: STT | B5: M số | C5: Họ và tên | D5: Giới tính | E5: Ngày tháng năm sinh | F5: Quốc tịch | G5: Nơi cư trú | H5: Số thẻ CCCD hoặc CMND hoặc hộ chiếu | I5: Trình độ chuyên môn kỹ thuật | J5: Bậc trình độ kỹ năng nghề | K5: Vị trí làm việc | L5: Loại hợp đồng lao động | M5: Thời điểm bắt đầu làm việc | N5: Tham gia bảo hiểm | Q5: Tiền lương | R5: Phụ cấp | S5: Nâng bậc, nâng lương | T5: Số ngày nghỉ trong năm | U5: Số giờ làm thêm | V5: Hưởng chế độ BHXH, BHYT, BHTN | W5: Học nghề, đào tạo, bồi dưỡng, nâng cao trình độ kỹ năng nghề | X5: Kỷ luật lao động, trách nhiệm vật chất | Y5: Tai nạn lao động, bệnh nghề nghiệp | Z5: Thời điểm chấm dứt hợp đồng lao động và lý do
N6: BHXH | O6: BHYT | P6: BHTN
A7: 1 | B7: A268 | C7: Nguyễn Công Huân | D7: Nam | E7: 31483 | F7: Việt Nam | H7: 092086007417 | I7: Thạc sĩ | L7: Không xác định | M7: 41379 | N7: 41379 | O7: 41379 | P7: 41379 | Q7: 26000000 | R7: 0
A8: 2 | B8: A035 | C8: Nguyễn Nam Bình | D8: Nam | E8: 26344 | F8: Việt Nam | H8: 034072016055 | I8: Đại học | L8: Không xác định | M8: 34243 | N8: 34243 | O8: 34243 | P8: 34243 | Q8: 23000000 | R8: 0
A9: 3 | B9: A131 | C9: Trần Ngọc Văn | D9: Nam | E9: 28775 | F9: Việt Nam | H9: 089078019969 | I9: Đại học | L9: Không xác định | M9: 37104 | N9: 37104 | O9: 37104 | P9: 37104 | Q9: 21850000
A10: 4 | B10: A190 | C10: Trần Siêu Đẳng | D10: Nam | E10: 29335 | F10: Việt Nam | H10: 051080007405 | I10: Đại học | L10: Không xác định | M10: 39052 | N10: 39052 | O10: 39052 | P10: 39052 | Q10: 21850000
A11: 5 | B11: A391 | C11: Võ Quỳnh Như | D11: Nữ | E11: 34643 | F11: Việt Nam | H11: 087194013763 | I11: Đại học | L11: Không xác định | M11: 44713 | N11: 44713 | O11: 44713 | P11: 44713 | Q11: 6579000 | R11: 0
A12: 6 | B12: A279 | C12: Nguyễn Thanh Duy | D12: Nam | E12: 32952 | F12: Việt Nam | H12: 092090014793 | I12: Đại học | L12: Không xác định | M12: 41609 | N12: 41609 | O12: 41609 | P12: 41609 | Q12: 7673000 | R12: 2365000
A13: 7 | B13: A255 | C13: Trầm Trung Bích Thảo | D13: Nữ | E13: 32616 | F13: Việt Nam | H13: 094189000207 | I13: Đại học | L13: Không xác định | M13: 40977 | N13: 40977 | O13: 40977 | P13: 40977 | Q13: 7673000 | R13: 1892000
A14: 8 | B14: A358 | C14: Trần Ngọc Bảo Trân | D14: Nữ | E14: 34769 | F14: Việt Nam | H14: 092195009932 | I14: Đại học | L14: Không xác định | M14: 43282 | N14: 43282 | O14: 43282 | P14: 43282 | Q14: 7105000 | R14: 0
A15: 9 | B15: A369 | C15: Phan Thanh Trường | D15: Nam | E15: 35312 | F15: Việt Nam | H15: 087096014501 | I15: Đại học | L15: Không xác định | M15: 43647 | N15: 43647 | O15: 43647 | P15: 43647 | Q15: 7105000 | R15: 0
A16: 10 | B16: A385 | C16: Nguyễn Thị Thùy Miên | D16: Nữ | E16: 35554 | F16: Việt Nam | H16: 089197013110 | I16: Trung cấp | L16: Không xác định | M16: 44349 | N16: 44349 | O16: 44349 | P16: 44349 | Q16: 7105000 | R16: 0
A17: 11 | B17: A289 | C17: Hoàng Thị Thanh Mai | D17: Nữ | E17: 29150 | F17: Việt Nam | H17: 036179013255 | I17: Đại học | L17: Không xác định | M17: 41744 | N17: 41744 | O17: 41744 | P17: 41744 | Q17: 6375000 | R17: 0
A18: 12 | B18: A215 | C18: Nguyễn Thị Mỹ Nhiên | D18: Nữ | E18: 30333 | F18: Việt Nam | H18: 093183000309 | I18: Đại học | L18: Không xác định | M18: 39539 | N18: 39539 | O18: 39539 | P18: 39539 | Q18: 8287000 | R18: 0
A19: 13 | B19: A408 | C19: Trần Chí Đan | D19: Nam | E19: 36024 | F19: Việt Nam | H19: 092098000305 | I19: Đại học | L19: Không xác định | M19: 45231 | N19: 45231 | O19: 45231 | P19: 45231 | Q19: 6579000 | R19: 0
A20: 14 | B20: A414 | C20: Trần Văn Giàu | D20: Nam | E20: 37034 | F20: Việt Nam | H20: 093201003354 | I20: Đại học | L20: 12 tháng | M20: 45444 | N20: 45444 | O20: 45444 | P20: 45444 | Q20: 5466000 | R20: 0
A21: 15 | B21: C109 | C21: Lê Huy Minh | D21: Nam | E21: 28537 | F21: Việt Nam | H21: 038078000972 | I21: Đại học | L21: Không xác định | M21: 34824 | N21: 34824 | O21: 34824 | P21: 34824 | Q21: 8287000 | R21: 1892000
A22: 16 | B22: A288 | C22: Nguyễn Hải Đăng | D22: Nam | E22: 33156 | F22: Việt Nam | H22: 093090005260 | I22: Cao Đẳng | L22: Không xác định | M22: 41730 | N22: 41730 | O22: 41730 | P22: 41730 | Q22: #N/A | R22: #N/A
A23: 17 | B23: A339 | C23: Lê Minh Toàn | D23: Nam | E23: 33063 | F23: Việt Nam | H23: 092090001386 | I23: Đại học | L23: Không xác định | M23: 42675 | N23: 42675 | O23: 42675 | P23: 42675 | Q23: 8539000 | R23: 1892000
A24: 18 | B24: C562 | C24: Trần Ngọc Sáng | D24: Nam | E24: 34773 | F24: Việt Nam | H24: 091095006772 | I24: Phổ thông | L24: Không xác định | M24: 44501 | N24: 44501 | O24: 44501 | P24: 44501 | Q24: 6647000 | R24: 0
A25: 19 | B25: A419 | C25: Nguyễn Trương Bình Nguyên | D25: Nam | E25: 37611 | F25: Việt Nam | H25: 092202006332 | I25: Đại học | L25: 12 tháng | M25: 45709 | N25: 45709 | O25: 45709 | P25: 45709 | Q25: 5955000
A26: 20 | B26: P009 | C26: Lê Minh Tuấn | D26: Nam | E26: 36873 | F26: Việt Nam | H26: 092200006987 | I26: Đại học | L26: 12 tháng | M26: 45505 | N26: 45505 | O26: 45505 | P26: 45505 | Q26: 4410000
A27: 21 | B27: A422 | C27: Huỳnh Dương Phương Anh | D27: Nữ | E27: 37460 | F27: Việt Nam | H27: 093302001656 | I27: Đại học | L27: 12 tháng | M27: 45748 | N27: 45748 | O27: 45748 | P27: 45748 | Q27: 6135000
A28: 22 | B28: A424 | C28: Đặng Thị Uyên Nhi | D28: Nữ | E28: 44710 | F28: Việt Nam | H28: 087302004502 | I28: Cao Đẳng | L28: 12 tháng | M28: 45809 | N28: 45809 | O28: 45809 | P28: 45809 | Q28: 6135000
A29: 23 | B29: A429 | C29: Lê Võ Nhật Khoa | D29: Nam | E29: 37948 | F29: Việt Nam | H29: 092203005594 | I29: Đại học | L29: 12 tháng | M29: 45962 | N29: 45962 | O29: 45962 | P29: 45962 | Q29: 6135000
A30: 24 | B30: A246 | C30: Trần Minh Giàu | D30: Nam | E30: 30348 | F30: Việt Nam | H30: 092083009975 | I30: Đại học | L30: Không xác định | M30: 40665 | N30: 40665 | O30: 40665 | P30: 40665 | Q30: 7046000 | R30: 0
A31: 25 | B31: A327 | C31: Lê Trung Hiếu | D31: Nam | E31: 32620 | F31: Việt Nam | H31: 086089010769 | I31: Đại học | L31: Không xác định | M31: 42370 | N31: 42370 | O31: 42370 | P31: 42370 | Q31: 6647000 | R31: 0
A32: 26 | B32: H062 | C32: Lê Bằng Thẳng | D32: Nam | E32: 31643 | F32: Việt Nam | H32: 093086003738 | I32: Đại học | L32: Không xác định | M32: 42156 | N32: 42156 | O32: 42156 | P32: 42156 | Q32: 6647000 | R32: 0
A33: 27 | B33: A328 | C33: Huỳnh Phú Nhân | D33: Nam | E33: 34633 | F33: Việt Nam | H33: 092094005136 | I33: Cao đẳng | L33: Không xác định | M33: 42370 | N33: 42370 | O33: 42370 | P33: 42370 | Q33: 7046000 | R33: 0
A34: 28 | B34: A367 | C34: Lương Phú Vinh | D34: Nam | E34: 33917 | F34: Việt Nam | H34: 092092010946 | I34: Đại học | L34: Không xác định | M34: 43405 | N34: 43405 | O34: 43405 | P34: 43405 | Q34: 6647000 | R34: 0
A35: 29 | B35: A380 | C35: Nguyễn Hoài Phong | D35: Nam | E35: 35117 | F35: Việt Nam | H35: 089096016279 | I35: Cao Đẳng | L35: Không xác định | M35: 44044 | N35: 44044 | O35: 44044 | P35: 44044 | Q35: 6647000 | R35: 0
A36: 30 | B36: A344 | C36: Lê Trọng Nhơn | D36: Nam | E36: 33633 | F36: Việt Nam | H36: 087092017349 | I36: Đại học | L36: Không xác định | M36: 42736 | N36: 42736 | O36: 42736 | P36: 42736 | Q36: 7105000 | R36: 2205000
A37: 31 | B37: A394 | C37: Nguyễn Hứa Kim Thảo | D37: Nữ | E37: 35524 | F37: Việt Nam | H37: 092197011285 | I37: Đại học | L37: Không xác định | M37: 44805 | N37: 44805 | O37: 44805 | P37: 44805 | Q37: 5466000 | R37: 0
A38: 32 | B38: A397 | C38: Mạch Chí Thiện | D38: Nam | E38: 30482 | F38: Việt Nam | H38: 086083000292 | I38: Đại học | L38: Không xác định | M38: 44866 | N38: 44866 | O38: 44866 | P38: 44866 | Q38: 10971000 | R38: 1656000
A39: 33 | B39: A403 | C39: Ngô Văn Tài | D39: Nam | E39: 35231 | F39: Việt Nam | H39: 089096013188 | I39: Đại học | L39: Không xác định | M39: 45113 | N39: 45113 | O39: 45113 | P39: 45113 | Q39: 6271000 | R39: 0
A40: 34 | B40: A283 | C40: Cao Văn Được | D40: Nam | E40: 32488 | F40: Việt Nam | H40: 092088000675 | I40: Đại học | L40: Không xác định | M40: 41641 | N40: 41641 | O40: 41641 | P40: 41641 | Q40: 6785000 | R40: 0
...

Sheet T1-26
B1: DANH SÁCH NHÂN SỰ | R1: Ngày làm | S1: Năm công tác | T1: Ngày tính
B2: XÍ NGHIỆP PHÂN BÓN HÓA CHẤT | R2: 37087 | S2: =DATEDIF(R2,T2,"Y") & " NĂM " &DATEDIF(R2,T2,"YM") & " THÁNG " & DATEDIF(R2,T2, "MD") & " NGÀY " -> 7 NĂM 5 THÁNG 16 NGÀY | T2: 39813
A4: STT | B4: STT | C4: MÃ SỐ | E4: HỌ VÀ TÊN | G4: Lương | H4: Phụ cấp | I4: GIỚI TÍNH | K4: DÂN TỘC | L4: TÔN GIÁO | M4: CHỨC VỤ | N4: ĐƠN VỊ CÔNG TÁC | O4: NGÀY SINH | P4: NGÀY LÀM | Q4: HĐLĐ | R4: SỐ HĐLĐ | S4: NĂM CÔNG TÁC | T4: CMND | U4: CCCD | V4: Quốc tịch | W4: Nâng Lương | X4: Số ngày nghỉ trong năm | Y4: Số giờ làm thêm | Z4: Đào tạo bồi dưỡng chuyên môn KT | AA4: Kỷ luật lao động | AB4: Trách nhiệm vật chất | AC4: Tai nạn lao động | AD4: Bệnh nghề nghiệp | AE4: Thời điểm chấm dứt HĐLĐ | AF4: Lý do | AG4: NGÀY CẤP | AI4: NƠI CẤP | AJ4: NƠI SINH | AK4: ĐỊA CHỈ THƯỜNG TRÚ | AL4: ĐỊA CHỈ HIỆN NAY | AM4: SỐ ĐIỆN THOẠI | AN4: TRÌNH ĐỘ | AO4: CHUYÊN NGÀNH | AP4: CÔNG VIỆC PHẢI LÀM | AQ4: Tuổi
A5: =IF(C5=0,"",SUBTOTAL(3,C$5:C5)) -> 1 | B5: 1 | C5: A268 | D5: =VLOOKUP(C5,Sheet4!$A$1:$B$300,2,0) -> 9213003755 | E5: Nguyễn Công Huân | F5: =VLOOKUP(D5,'Sheet1 (2)'!$D$11:$F$338,3,0) -> Nguyễn Công Huân | G5: =VLOOKUP(C5,'chuyển xếp 2024'!$C$5:$W$328,17,0) -> 26000000 | H5: =VLOOKUP(C5,'chuyển xếp 2024'!$C$5:$W$328,19,0) -> 0 | I5: Nam | J5: =IF(I5="nữ",0,1) -> 1 | K5: Kinh | L5: Không | M5: TGĐ | O5: 31483 | P5: 41379 | Q5: Không xác định | R5: 2 /HĐ/PBHC/16 | S5: =DATEDIF(P5,TODAY(),"Y") & " NĂM " &DATEDIF(P5,TODAY(),"YM") & " THÁNG " & DATEDIF(P5,TODAY(), "MD") & " NGÀY " -> 13 NĂM 4 THÁNG 4 NGÀY | T5: 092086007417 | U5: =VLOOKUP(C5,Sheet5!$B$2:$G$253,6,0) -> 092086007417 | AG5: 44743 | AI5: Cục cảnh sát QLHC về TTXH | AJ5: Phường Xuân Khánh, Quận Ninh Kiều, Thành phố Cần Thơ | AK5: Số 166 Nguyễn Thị Minh Khai, Phường Xuân Khánh, Quận Ninh Kiều, TP Cần Thơ. | AL5: Số 9 Cồn Khương, Phường Cái Khế, Quận Ninh Kiều, Thành phố Cần Thơ | AN5: Thạc sĩ | AO5: Bác sĩ & Quản trị Kinh doanh | AQ5: =DATEDIF(O5,TODAY(),"y") -> 40
A6: =IF(C6=0,"",SUBTOTAL(3,C$5:C6)) -> 2 | B6: 2 | C6: A035 | D6: =VLOOKUP(C6,Sheet4!$A$1:$B$300,2,0) -> 5496032611 | E6: Nguyễn Nam Bình | F6: =VLOOKUP(D6,'Sheet1 (2)'!$D$11:$F$338,3,0) -> Nguyễn Nam Bình | G6: =VLOOKUP(C6,'chuyển xếp 2024'!$C$5:$W$328,17,0) -> 23000000 | H6: =VLOOKUP(C6,'chuyển xếp 2024'!$C$5:$W$328,19,0) -> 0 | I6: Nam | J6: =IF(I6="nữ",0,1) -> 1 | K6: Kinh | L6: Không | M6: Phó TGĐ kiêm Chủ tịch HĐTV Cty TNHH Hữu cơ đậm đặc | O6: 26344 | P6: 34243 | Q6: Không xác định | S6: =DATEDIF(P6,TODAY(),"Y") & " NĂM " &DATEDIF(P6,TODAY(),"YM") & " THÁNG " & DATEDIF(P6,TODAY(), "MD") & " NGÀY " -> 32 NĂM 10 THÁNG 18 NGÀY | T6: 034072016055 | U6: =VLOOKUP(C6,Sheet5!$B$2:$G$253,6,0) -> 034072016055 | AG6: 44522 | AI6: Cục cảnh sát QLHC về TTXH | AJ6: Thị trấn An Bài, Tỉnh Thái Bình. | AK6: U5 Nguyễn Ngọc Trai, phường Xuân Khánh, quận Ninh Kiều, TP Cần Thơ. | AL6: U5 Nguyễn Ngọc Trai, phường Xuân Khánh, quận Ninh Kiều, TP Cần Thơ. | AN6: Đại học | AO6: Kế toán tài chính | AQ6: =DATEDIF(O6,TODAY(),"y") -> 54
A7: =IF(C7=0,"",SUBTOTAL(3,C$5:C7)) -> 3 | B7: 3 | C7: A131 | D7: =VLOOKUP(C7,Sheet4!$A$1:$B$300,2,0) -> 5402005143 | E7: Trần Ngọc Văn | F7: =VLOOKUP(D7,'Sheet1 (2)'!$D$11:$F$338,3,0) -> Trần Ngọc Văn | G7: 21850000 | I7: Nam | J7: =IF(I7="nữ",0,1) -> 1 | K7: Kinh | L7: Phật | M7: P tổng giám đốc | N7: Phòng TT | O7: 28775 | P7: 37104 | Q7: Không xác định | R7: 16 /HĐ/PBHC/16 | S7: =DATEDIF(P7,TODAY(),"Y") & " NĂM " &DATEDIF(P7,TODAY(),"YM") & " THÁNG " & DATEDIF(P7,TODAY(), "MD") & " NGÀY " -> 25 NĂM 0 THÁNG 18 NGÀY | T7: 089078019969 | U7: =VLOOKUP(C7,Sheet5!$B$2:$G$253,6,0) -> 089078019969 | AI7: Cục cảnh sát QLHC về TTXH | AJ7: Xã Tân Hòa, Huyện Phú Tân, Tỉnh An Giang. | AK7: P. Mỹ Phước, TP Long Xuyên, T. An Giang | AL7: Khu TT Công An, P. An Hòa, Q. Ninh Kiều, TP Cần Thơ | AM7: 0639664171 | AN7: Đại học | AO7: Kỹ sư nông nghiệp | AP7: Theo chức năng nhiệm vụ được TGĐ giao | AQ7: =DATEDIF(O7,TODAY(),"y") -> 47
A8: =IF(C8=0,"",SUBTOTAL(3,C$5:C8)) -> 4 | B8: 4 | C8: A190 | D8: =VLOOKUP(C8,Sheet4!$A$1:$B$300,2,0) -> 6506006858 | E8: Trần Siêu Đẳng | F8: =VLOOKUP(D8,'Sheet1 (2)'!$D$11:$F$338,3,0) -> Trần Siêu Đẳng | G8: 21850000 | I8: Nam | J8: =IF(I8="nữ",0,1) -> 1 | K8: Kinh | L8: Không | M8: P tổng Giám đốc | N8: VP XN. PB&HC | O8: 29335 | P8: 39052 | Q8: Không xác định | R8: 199 /HĐ/PBHC/16 | S8: =DATEDIF(P8,TODAY(),"Y") & " NĂM " &DATEDIF(P8,TODAY(),"YM") & " THÁNG " & DATEDIF(P8,TODAY(), "MD") & " NGÀY " -> 19 NĂM 8 THÁNG 18 NGÀY | T8: 212021584 | U8: =VLOOKUP(C8,Sheet5!$B$2:$G$253,6,0) -> 051080007405 | AG8: 40938 | AI8: Cục cảnh sát QLHC về TTXH | AJ8: Xã Phổ Phong, Huyện Đức Phổ, Tỉnh Quảng Ngãi. | AK8: 130 đường 30/4, Phường Hưng Lợi, Quận Ninh Kiều, TP.Cần Thơ. | AN8: Đại học | AO8: Công nghệ hóa học | AP8: Theo chức năng nhiệm vụ được Tổng giám đốc giao | AQ8: =DATEDIF(O8,TODAY(),"y") -> 46
A9: =IF(C9=0,"",SUBTOTAL(3,C$5:C9)) -> 5 | B9: 5 | C9: A391 | D9: =VLOOKUP(C9,Sheet4!$A$1:$B$300,2,0) -> 8616014612 | E9: Võ Quỳnh Như | F9: =VLOOKUP(D9,'Sheet1 (2)'!$D$11:$F$338,3,0) -> Võ Quỳnh Như | G9: =VLOOKUP(C9,'chuyển xếp 2024'!$C$5:$W$328,21,0) -> 6579000 | H9: =VLOOKUP(C9,'chuyển xếp 2024'!$C$5:$W$328,19,0) -> 0 | I9: Nữ | J9: =IF(I9="nữ",0,1) -> 0 | K9: Kinh | L9: Không | N9: Phòng XNK | O9: 34643 | P9: 44713 | Q9: Không xác định | R9: 17/HĐ-PBHC/2022 | S9: =DATEDIF(P9,TODAY(),"Y") & " NĂM " &DATEDIF(P9,TODAY(),"YM") & " THÁNG " & DATEDIF(P9,TODAY(), "MD") & " NGÀY " -> 4 NĂM 2 THÁNG 18 NGÀY | T9: 341725735 | U9: =VLOOKUP(C9,Sheet5!$B$2:$G$253,6,0) -> 087194013763 | AG9: 40353 | AI9: Cục cảnh sát QLHC về TTXH | AJ9: 138 Ấp An Lợi, X. An Khánh, H. Châu Thành, T. Đồng Tháp | AK9: 138 Ấp An Lợi, X. An Khánh, H. Châu Thành, T. Đồng Tháp | AM9: 0979 176 415 | AN9: Đại học | AO9: Ngôn ngữ Anh | AP9: Do Trưởng phòng phân công công việc | AQ9: =DATEDIF(O9,TODAY(),"y") -> 31
A10: =IF(C10=0,"",SUBTOTAL(3,C$5:C10)) -> 6 | B10: 1 | C10: A279 | D10: =VLOOKUP(C10,Sheet4!$A$1:$B$300,2,0) -> 9212004554 | E10: Nguyễn Thanh Duy | F10: =VLOOKUP(D10,'Sheet1 (2)'!$D$11:$F$338,3,0) -> Nguyễn Thanh Duy | G10: =VLOOKUP(C10,'chuyển xếp 2024'!$C$5:$W$328,17,0) -> 7673000 | H10: =VLOOKUP(C10,'chuyển xếp 2024'!$C$5:$W$328,19,0) -> 2365000 | I10: Nam | J10: =IF(I10="nữ",0,1) -> 1 | K10: Kinh | L10: Không | M10: Trưởng phòng | N10: P. KHVT | O10: 32952 | P10: 41609 | Q10: Không xác định | R10: 4 /HĐ/PBHC/16 | S10: =DATEDIF(P10,TODAY(),"Y") & " NĂM " &DATEDIF(P10,TODAY(),"YM") & " THÁNG " & DATEDIF(P10,TODAY(), "MD") & " NGÀY " -> 12 NĂM 8 THÁNG 18 NGÀY | T10: 092090014793 | U10: =VLOOKUP(C10,Sheet5!$B$2:$G$253,6,0) -> 092090014793 | AI10: Cục cảnh sát QLHC về TTXH | AJ10: Phường Thới Bình, Quận Ninh Kiều, Thành phố Cần Thơ. | AK10: 228/74A Phạm Ngũ Lão, P. An Hòa, Q. NK, TPCT | AL10: 228/74A Phạm Ngũ Lão, P. An Hòa, Q. NK, TPCT | AM10: 0939155888 | AN10: Đại học | AO10: KT Ngoại Thương | AP10: Do Trưởng phòng phân công công việc | AQ10: =DATEDIF(O10,TODAY(),"y") -> 36
A11: =IF(C11=0,"",SUBTOTAL(3,C$5:C11)) -> 7 | B11: 2 | C11: A255 | D11: =VLOOKUP(C11,Sheet4!$A$1:$B$300,2,0) -> 9212004139 | E11: Trầm Trung Bích Thảo | F11: =VLOOKUP(D11,'Sheet1 (2)'!$D$11:$F$338,3,0) -> Trầm Trung Bích Thảo | G11: =VLOOKUP(C11,'chuyển xếp 2024'!$C$5:$W$328,17,0) -> 7673000 | H11: =VLOOKUP(C11,'chuyển xếp 2024'!$C$5:$W$328,19,0) -> 1892000 | I11: Nữ | J11: =IF(I11="nữ",0,1) -> 0 | K11: Kinh | L11: Không | M11: Phó phòng | N11: P. KHVT | O11: 32616 | P11: 40977 | Q11: Không xác định | R11: 6 /HĐ/PBHC/16 | S11: =DATEDIF(P11,TODAY(),"Y") & " NĂM " &DATEDIF(P11,TODAY(),"YM") & " THÁNG " & DATEDIF(P11,TODAY(), "MD") & " NGÀY " -> 14 NĂM 5 THÁNG 10 NGÀY | T11: 094189000207 | U11: =VLOOKUP(C11,Sheet5!$B$2:$G$253,6,0) -> 094189000207 | AG11: 38540 | AI11: Cục cảnh sát QLHC về TTXH | AJ11: Xã Đại Tâm, Huyện Mỹ Xuyên, Tỉnh Sóc Trăng | AK11: 63A hẻm 3 Mậu Thân, P. Xuân Khánh, Q. Ninh Kiều, TP. Cần Thơ | AL11: 63A hẻm 3 Mậu Thân, P. Xuân Khánh, Q. Ninh Kiều, TP. Cần Thơ | AM11: 0988978619 | AN11: Đại học | AO11: Công nghệ hóa học | AP11: Theo chức năng nhiệm vụ được TGĐ giao | AQ11: =DATEDIF(O11,TODAY(),"y") -> 37
A12: =IF(C12=0,"",SUBTOTAL(3,C$5:C12)) -> 8 | B12: 3 | C12: A358 | D12: =VLOOKUP(C12,Sheet4!$A$1:$B$300,2,0) -> 9221356007 | E12: Trần Ngọc Bảo Trân | F12: =VLOOKUP(D12,'Sheet1 (2)'!$D$11:$F$338,3,0) -> Trần Ngọc Bảo Trân | G12: =VLOOKUP(C12,'chuyển xếp 2024'!$C$5:$W$328,21,0) -> 7105000 | H12: =VLOOKUP(C12,'chuyển xếp 2024'!$C$5:$W$328,19,0) -> 0 | I12: Nữ | J12: =IF(I12="nữ",0,1) -> 0 | K12: Kinh | L12: Không | N12: P. KHVT | O12: 34769 | P12: 43282 | Q12: Không xác định | R12: 15.1 /HĐ-PBHC/19 | S12: =DATEDIF(P12,TODAY(),"Y") & " NĂM " &DATEDIF(P12,TODAY(),"YM") & " THÁNG " & DATEDIF(P12,TODAY(), "MD") & " NGÀY " -> 8 NĂM 1 THÁNG 18 NGÀY | T12: 362488362 | U12: =VLOOKUP(C12,Sheet5!$B$2:$G$253,6,0) -> 092195009932 | AG12: 41193 | AI12: Cục cảnh sát QLHC về TTXH | AJ12: Phường Xuân Khánh, Quận Ninh Kiều, Thành phố Cần Thơ. | AK12: 126 Lê Anh Xuân, Phường An Hòa, Quận Ninh Kiều, Thành phố Cần Thơ. | AL12: 126 Lê Anh Xuân, Phường An Hòa, Quận Ninh Kiều, Thành phố Cần Thơ. | AM12: 0834500115 | AN12: Đại học | AO12: Cử nhân sinh học | AP12: Do Trưởng phòng phân công công việc | AQ12: =DATEDIF(O12,TODAY(),"y") -> 31
A13: =IF(C13=0,"",SUBTOTAL(3,C$5:C13)) -> 9 | B13: 4 | C13: A369 | D13: =VLOOKUP(C13,Sheet4!$A$1:$B$300,2,0) -> 8722989947 | E13: Phan Thanh Trường | F13: =VLOOKUP(D13,'Sheet1 (2)'!$D$11:$F$338,3,0) -> Phan Thanh Trường | G13: =VLOOKUP(C13,'chuyển xếp 2024'!$C$5:$W$328,21,0) -> 7105000 | H13: =VLOOKUP(C13,'chuyển xếp 2024'!$C$5:$W$328,19,0) -> 0 | I13: Nam | J13: =IF(I13="nữ",0,1) -> 1 | K13: Kinh | L13: Không | N13: P. KHVT | O13: 35312 | P13: 43647 | Q13: Không xác định | R13: 04.1/HĐ-PBHC/20 | S13: =DATEDIF(P13,TODAY(),"Y") & " NĂM " &DATEDIF(P13,TODAY(),"YM") & " THÁNG " & DATEDIF(P13,TODAY(), "MD") & " NGÀY " -> 7 NĂM 1 THÁNG 18 NGÀY | T13: 341841411 | U13: =VLOOKUP(C13,Sheet5!$B$2:$G$253,6,0) -> 087096014501 | AG13: 41081 | AI13: Cục cảnh sát QLHC về TTXH | AJ13: Xã Long Hậu, Huyện Lai Vung, Tỉnh Đồng Tháp. | AK13: 93/24 Nguyễn Việt Dũng, P. An Thới, Q. Bình Thủy, TP Cần Thơ | AL13: 93/24 Nguyễn Việt Dũng, P. An Thới, Q. Bình Thủy, TP Cần Thơ | AM13: 0907902546 | AN13: Đại học | AO13: Marketing | AP13: Do Trưởng phòng phân công công việc | AQ13: =DATEDIF(O13,TODAY(),"y") -> 29
A14: =IF(C14=0,"",SUBTOTAL(3,C$5:C14)) -> 10 | B14: 5 | C14: A385 | D14: 8923922038 | E14: Nguyễn Thị Thùy Miên | F14: =VLOOKUP(D14,'Sheet1 (2)'!$D$11:$F$338,3,0) -> Nguyễn Thị Thùy Miên | G14: =VLOOKUP(C14,'chuyển xếp 2024'!$C$5:$W$328,21,0) -> 7105000 | H14: =VLOOKUP(C14,'chuyển xếp 2024'!$C$5:$W$328,19,0) -> 0 | I14: Nữ | J14: =IF(I14="nữ",0,1) -> 0 | K14: Kinh | L14: Không | N14: P. KHVT | O14: 35554 | P14: 44349 | Q14: Không xác định | R14: 18/HĐ-PBHC/2021 | S14: =DATEDIF(P14,TODAY(),"Y") & " NĂM " &DATEDIF(P14,TODAY(),"YM") & " THÁNG " & DATEDIF(P14,TODAY(), "MD") & " NGÀY " -> 5 NĂM 2 THÁNG 17 NGÀY | T14: 089197013110 | U14: =VLOOKUP(C14,Sheet5!$B$2:$G$253,6,0) -> 089197013110 | AG14: 44916 | AI14: Cục cảnh sát QLHC về TTXH | AJ14: Xã Long Điền B, Huyện Chợ Mới, Tỉnh An Giang | AK14: Ấp Long Quới 1, Xã Long Điền B, Huyện Chợ Mới, Tỉnh An Giang | AL14: 95 Trần Chiên, P. Lê Bình, Q. Cái Răng, TP Cần Thơ | AM14: 0969342484 | AN14: Đại học | AO14: Công nghệ kỹ thuật Hóa học | AP14: Do Trưởng phòng phân công công việc | AQ14: =DATEDIF(O14,TODAY(),"y") -> 29
A15: =IF(C15=0,"",SUBTOTAL(3,C$5:C15)) -> 11 | B15: 6 | C15: A289 | D15: =VLOOKUP(C15,Sheet4!$A$1:$B$300,2,0) -> 5499003403 | E15: Hoàng Thị Thanh Mai | F15: =VLOOKUP(D15,'Sheet1 (2)'!$D$11:$F$338,3,0) -> Hoàng Thị Thanh Mai | G15: =VLOOKUP(C15,'chuyển xếp 2024'!$C$5:$W$328,21,0) -> 6375000 | H15: =VLOOKUP(C15,'chuyển xếp 2024'!$C$5:$W$328,19,0) -> 0 | I15: Nữ | J15: =IF(I15="nữ",0,1) -> 0 | K15: Kinh | L15: Không | N15: P. KHVT | O15: 29150 | P15: 41744 | Q15: Không xác định | R15: 29 /HĐ/PBHC/16 | S15: =DATEDIF(P15,TODAY(),"Y") & " NĂM " &DATEDIF(P15,TODAY(),"YM") & " THÁNG " & DATEDIF(P15,TODAY(), "MD") & " NGÀY " -> 12 NĂM 4 THÁNG 4 NGÀY | T15: 036179013255 | U15: =VLOOKUP(C15,Sheet5!$B$2:$G$253,6,0) -> 036179013255 | AI15: Cục cảnh sát QLHC về TTXH | AJ15: Phường Trà Nóc, Quận Bình Thuỷ, Thành phố Cần Thơ. | AK15: B11 Nguyễn Thông, Phường An Thới, Quận Ô Môn, Thành phố Cần Thơ. | AL15: B11 Nguyễn Thông, Phường An Thới, Quận Ô Môn, Thành phố Cần Thơ. | AM15: 0972835009 | AN15: Trung cấp | AO15: Kế toán | AP15: Do Trưởng phòng phân công công việc | AQ15: =DATEDIF(O15,TODAY(),"y") -> 46
A16: =IF(C16=0,"",SUBTOTAL(3,C$5:C16)) -> 12 | B16: 7 | C16: A215 | D16: =VLOOKUP(C16,Sheet4!$A$1:$B$300,2,0) -> 9208007865 | E16: Nguyễn Thị Mỹ Nhiên | F16: =VLOOKUP(D16,'Sheet1 (2)'!$D$11:$F$338,3,0) -> Nguyễn Thị Mỹ Nhiên | G16: =VLOOKUP(C16,'chuyển xếp 2024'!$C$5:$W$328,21,0) -> 8287000 | H16: =VLOOKUP(C16,'chuyển xếp 2024'!$C$5:$W$328,19,0) -> 0 | I16: Nữ | J16: =IF(I16="nữ",0,1) -> 0 | K16: Kinh | L16: Không | N16: P. KHVT | O16: 30333 | P16: 39539 | Q16: Không xác định | R16: 308 /HĐ/PBHC/16 | S16: =DATEDIF(P16,TODAY(),"Y") & " NĂM " &DATEDIF(P16,TODAY(),"YM") & " THÁNG " & DATEDIF(P16,TODAY(), "MD") & " NGÀY " -> 18 NĂM 4 THÁNG 18 NGÀY | T16: 093183000309 | U16: =VLOOKUP(C16,Sheet5!$B$2:$G$253,6,0) -> 093183000309 | AI16: Cục cảnh sát QLHC về TTXH | AJ16: Xã Phú Hữu, Huyện Châu Thành, Tỉnh Hậu Giang | AK16: 24 Bế Văn Đàn, Phường An Hòa, Quận Ninh Kiều, Thành phố Cần Thơ. | AL16: 24 Bế Văn Đàn, Phường An Hòa, Quận Ninh Kiều, Thành phố Cần Thơ. | AN16: Đại học | AO16: Công nghệ hóa học | AP16: Do Trưởng phòng phân công công việc | AQ16: =DATEDIF(O16,TODAY(),"y") -> 43
A17: =IF(C17=0,"",SUBTOTAL(3,C$5:C17)) -> 13 | B17: 8 | C17: A408 | D17: =VLOOKUP(C17,Sheet4!$A$1:$B$300,2,0) -> 9222378283 | E17: Trần Chí Đan | F17: =VLOOKUP(D17,'Sheet1 (2)'!$D$11:$F$338,3,0) -> Trần Chí Đan | G17: =VLOOKUP(C17,'chuyển xếp 2024'!$C$5:$W$328,21,0) -> 6579000 | H17: =VLOOKUP(C17,'chuyển xếp 2024'!$C$5:$W$328,19,0) -> 0 | I17: Nam | J17: =IF(I17="nữ",0,1) -> 1 | K17: Kinh | L17: Không | N17: P. KHVT | O17: 36024 | P17: 45231 | Q17: Không xác định | R17: 57/HĐ/PBHC/2023 | S17: =DATEDIF(P17,TODAY(),"Y") & " NĂM " &DATEDIF(P17,TODAY(),"YM") & " THÁNG " & DATEDIF(P17,TODAY(), "MD") & " NGÀY " -> 2 NĂM 9 THÁNG 18 NGÀY | T17: 092098000305 | U17: 092098000305 | AG17: 2//8/10/2022 | AI17: Cục cảnh sát QLHC về TTXH | AJ17: Xã Trường Thành, huyện Thới Lai, Tp Cần Thơ | AK17: Ấp Trường Tây,Xã Trường Thành, huyện Thới Lai, Tp Cần Thơ | AN17: Đại học | AO17: Công nghệ sinh học | AP17: Do Trưởng phòng phân công công việc | AQ17: =DATEDIF(O17,TODAY(),"y") -> 28
A18: =IF(C18=0,"",SUBTOTAL(3,C$5:C18)) -> 14 | B18: 9 | C18: A414 | D18: =VLOOKUP(C18,Sheet4!$A$1:$B$300,2,0) -> 9320886452 | E18: Trần Văn Giàu | F18: =VLOOKUP(D18,'Sheet1 (2)'!$D$11:$F$338,3,0) -> Trần Văn Giàu | G18: =VLOOKUP(C18,'chuyển xếp 2024'!$C$5:$W$328,21,0) -> 5466000 | H18: =VLOOKUP(C18,'chuyển xếp 2024'!$C$5:$W$328,19,0) -> 0 | I18: Nam | J18: =IF(I18="nữ",0,1) -> 1 | K18: Kinh | L18: Không | N18: P. KHVT | O18: 37034 | P18: 45444 | Q18: 12 tháng | R18: 38/HĐ/PBHC/2024 | S18: =DATEDIF(P18,TODAY(),"Y") & " NĂM " &DATEDIF(P18,TODAY(),"YM") & " THÁNG " & DATEDIF(P18,TODAY(), "MD") & " NGÀY " -> 2 NĂM 2 THÁNG 18 NGÀY | T18: 93201003354 | U18: 093201003354 | AG18: 44326 | AI18: Cục cảnh sát QLHC về TTXH | AJ18: Xã Đại Thành, Tp Ngã Bãy, Hậu Giang. | AK18: Ấp Sơn Phú, Xã Đại Thành, Tp Ngã Bãy, Hậu Giang. | AN18: Cao Đẳng | AO18: Thiết kế, Đồ Họa | AP18: Do Trưởng phòng phân công công việc | AQ18: =DATEDIF(O18,TODAY(),"y") -> 25
A19: =IF(C19=0,"",SUBTOTAL(3,C$5:C19)) -> 15 | B19: 10 | C19: C109 | D19: =VLOOKUP(C19,Sheet4!$A$1:$B$300,2,0) -> 5496032498 | E19: Lê Huy Minh | F19: =VLOOKUP(D19,'Sheet1 (2)'!$D$11:$F$338,3,0) -> Lê Huy Minh | G19: =VLOOKUP(C19,'chuyển xếp 2024'!$C$5:$W$328,17,0) -> 8287000 | H19: =VLOOKUP(C19,'chuyển xếp 2024'!$C$5:$W$328,19,0) -> 1892000 | I19: Nam | J19: =IF(I19="nữ",0,1) -> 1 | K19: Kinh | L19: Không | M19: Phó phòng | N19: P. KHVT | O19: 28537 | P19: 34824 | Q19: Không xác định | R19: 8 /HĐ/PBHC/16 | S19: =DATEDIF(P19,TODAY(),"Y") & " NĂM " &DATEDIF(P19,TODAY(),"YM") & " THÁNG " & DATEDIF(P19,TODAY(), "MD") & " NGÀY " -> 31 NĂM 3 THÁNG 14 NGÀY | T19: 038078000972 | U19: =VLOOKUP(C19,Sheet5!$B$2:$G$253,6,0) -> 038078000972 | AG19: 36572 | AI19: Cục cảnh sát QLHC về TTXH | AJ19: Xã Hải Hòa, Huyện Tĩnh Gia, Tỉnh Thanh Hoá. | AK19: 183/6 Lê Hồng Phong, Phường Trà Nóc, Quận Bình Thuỷ, Thành phố Cần Thơ. | AL19: 183/6 Lê Hồng Phong, Phường Trà Nóc, Quận Bình Thuỷ, Thành phố Cần Thơ. | AM19: 0916413878 | AN19: Đại học | AO19: QTKD | AP19: Do Trưởng phòng phân công công việc | AQ19: =DATEDIF(O19,TODAY(),"y") -> 48
A20: =IF(C20=0,"",SUBTOTAL(3,C$5:C20)) -> 16 | B20: 11 | C20: A288 | D20: =VLOOKUP(C20,Sheet4!$A$1:$B$300,2,0) -> 9214004739 | E20: Nguyễn Hải Đăng | F20: =VLOOKUP(D20,'Sheet1 (2)'!$D$11:$F$338,3,0) -> Nguyễn Hải Đăng | G20: =VLOOKUP(C20,'chuyển xếp 2024'!$C$5:$W$328,21,0) -> #N/A | H20: =VLOOKUP(C20,'chuyển xếp 2024'!$C$5:$W$328,19,0) -> #N/A | I20: Nam | J20: =IF(I20="nữ",0,1) -> 1 | K20: Kinh | L20: Không | N20: P. KHVT | O20: 33156 | P20: 41730 | Q20: Không xác định | R20: 5 /HĐ/PBHC/16 | S20: =DATEDIF(P20,TODAY(),"Y") & " NĂM " &DATEDIF(P20,TODAY(),"YM") & " THÁNG " & DATEDIF(P20,TODAY(), "MD") & " NGÀY " -> 12 NĂM 4 THÁNG 18 NGÀY | T20: 093090005260 | U20: =VLOOKUP(C20,Sheet5!$B$2:$G$253,6,0) -> 093090005260 | AI20: Cục cảnh sát QLHC về TTXH | AJ20: Xã Thuận Hưng, Huyện Long Mỹ, Tỉnh Hậu Giang. | AK20: Cạnh 162/54 đường Trần Quang Diệu, P.An Thới, Q. Bình Thủy, TP. Cần Thơ | AL20: Cạnh 162/54 đường Trần Quang Diệu, P.An Thới, Q. Bình Thủy, TP. Cần Thơ | AM20: 0907441113 | AN20: Đại học | AO20: QTKD | AP20: Do Trưởng phòng phân công công việc | AQ20: =DATEDIF(O20,TODAY(),"y") -> 35
A21: =IF(C21=0,"",SUBTOTAL(3,C$5:C21)) -> 17 | B21: 12 | C21: A339 | D21: =VLOOKUP(C21,Sheet4!$A$1:$B$300,2,0) -> 9216023928 | E21: Lê Minh Toàn | F21: =VLOOKUP(D21,'Sheet1 (2)'!$D$11:$F$338,3,0) -> Lê Minh Toàn | G21: =VLOOKUP(C21,'chuyển xếp 2024'!$C$5:$W$328,21,0) -> 8539000 | H21: =VLOOKUP(C21,'chuyển xếp 2024'!$C$5:$W$328,19,0) -> 1892000 | I21: Nam | J21: =IF(I21="nữ",0,1) -> 1 | K21: Kinh | L21: Không | N21: P. KHVT | O21: 33063 | P21: 42675 | Q21: Không xác định | R21: 14 /HĐ/PBHC/16 | S21: =DATEDIF(P21,TODAY(),"Y") & " NĂM " &DATEDIF(P21,TODAY(),"YM") & " THÁNG " & DATEDIF(P21,TODAY(), "MD") & " NGÀY " -> 9 NĂM 9 THÁNG 18 NGÀY | T21: 092090001386 | U21: =VLOOKUP(C21,Sheet5!$B$2:$G$253,6,0) -> 092090001386 | AG21: 42543 | AI21: Cục cảnh sát QLHC về TTXH | AJ21: Phường Xuân Khánh, Quận Ninh Kiều, Thành phố Cần Thơ. | AK21: 9/126 KDC số 9, đường 30/4, Phường Xuân Khánh, Quận Ninh Kiều, TP. Cần Thơ. | AL21: 9/126 KDC số 9, đường 30/4, Phường Xuân Khánh, Quận Ninh Kiều, TP. Cần Thơ. | AM21: 0919027948 | AN21: Đại học | AO21: Kế toán | AP21: Do Trưởng phòng phân công công việc | AQ21: =DATEDIF(O21,TODAY(),"y") -> 36
A22: =IF(C22=0,"",SUBTOTAL(3,C$5:C22)) -> 18 | B22: 13 | C22: C562 | D22: =VLOOKUP(C22,Sheet4!$A$1:$B$300,2,0) -> 9121911947 | E22: Trần Ngọc Sáng | F22: =VLOOKUP(D22,'Sheet1 (2)'!$D$11:$F$338,3,0) -> Trần Ngọc Sáng | G22: =VLOOKUP(C22,'chuyển xếp 2024'!$C$5:$W$328,21,0) -> 6647000 | H22: =VLOOKUP(C22,'chuyển xếp 2024'!$C$5:$W$328,19,0) -> 0 | I22: Nam | J22: =IF(I22="nữ",0,1) -> 1 | K22: Kinh | L22: Không | N22: P. KHVT | O22: 34773 | P22: 44501 | Q22: Không xác định | R22: 23/HĐ-PBHC/2021 | S22: =DATEDIF(P22,TODAY(),"Y") & " NĂM " &DATEDIF(P22,TODAY(),"YM") & " THÁNG " & DATEDIF(P22,TODAY(), "MD") & " NGÀY " -> 4 NĂM 9 THÁNG 18 NGÀY | T22: 371665103 | U22: 091095006772 | AG22: 43109 | AI22: Cục cảnh sát QLHC về TTXH | AJ22: TT Kiên Lương, H. Kiên Lương, T. Kiên Giang | AK22: 14 Tổ 19 khu phố cư xá mới, TT Kiên Lương, H. Kiên Lương, T. Kiên Giang | AM22: 0888 664 550 | AN22: Cao Đẳng | AO22: Tài chính - Ngân hàng | AP22: Do Trưởng phòng phân công công việc | AQ22: =DATEDIF(O22,TODAY(),"y") -> 31
A23: =IF(C23=0,"",SUBTOTAL(3,C$5:C23)) -> 19 | B23: 14 | C23: A419 | D23: 9221326375 | E23: Nguyễn Trương Bình Nguyên | F23: =VLOOKUP(D23,'Sheet1 (2)'!$D$11:$F$338,3,0) -> Nguyễn Trương Bình Nguyên | G23: 5955000 | I23: Nam | J23: =IF(I23="nữ",0,1) -> 1 | K23: Kinh | L23: Không | N23: P. KHVT | O23: 37611 | P23: 45709 | Q23: 12 tháng | R23: 01/HĐ-PBHC/2025 | S23: =DATEDIF(P23,TODAY(),"Y") & " NĂM " &DATEDIF(P23,TODAY(),"YM") & " THÁNG " & DATEDIF(P23,TODAY(), "MD") & " NGÀY " -> 1 NĂM 5 THÁNG 29 NGÀY | T23: 092202006332 | U23: 092202006332 | AG23: 44816 | AI23: Cục cảnh sát QLHC về TTXH | AJ23: Xuân Khánh, Ninh Kiều, Tp Cần Thơ | AK23: U5 Nguyễn Ngọc Trai, phường Xuân Khánh, quận Ninh Kiều, TP Cần Thơ. | AL23: U5 Nguyễn Ngọc Trai, phường Xuân Khánh, quận Ninh Kiều, TP Cần Thơ. | AM23: 962973361 | AN23: Đại học | AO23: Kinh tế nông nghiệp | AP23: Do Trưởng phòng phân công công việc | AQ23: =DATEDIF(O23,TODAY(),"y") -> 23
A24: =IF(C24=0,"",SUBTOTAL(3,C$5:C24)) -> 20 | B24: 15 | C24: P009 | D24: 9897325409 | E24: Lê Minh Tuấn | F24: =VLOOKUP(D24,'Sheet1 (2)'!$D$11:$F$338,3,0) -> Lê Minh Tuấn | G24: 4410000 | I24: Nam | J24: =IF(I24="nữ",0,1) -> 1 | K24: Kinh | L24: Không | N24: Nhân viên TT BG | O24: 36873 | P24: 45505 | Q24: 12 tháng | R24: 50/HĐLĐ-PBHC/2024 | S24: =DATEDIF(P24,TODAY(),"Y") & " NĂM " &DATEDIF(P24,TODAY(),"YM") & " THÁNG " & DATEDIF(P24,TODAY(), "MD") & " NGÀY " -> 2 NĂM 0 THÁNG 18 NGÀY | T24: 092200006987 | U24: 092200006987 | AG24: 22/11/2021 | AI24: Cục cảnh sát QLHC về TTXH | AJ24: Hưng Lợi, Ninh Kiều, Tp Cấn Thơ | AK24: 9/126 KDC số 9, Phường Xuân Khánh, Quận Ninh Kiều, TP. Cần Thơ. | AL24: 9/126 KDC số 9, Phường Xuân Khánh, Quận Ninh Kiều, TP. Cần Thơ. | AN24: Phổ thông | AP24: Do Trưởng bộ phận phân công công việc | AQ24: =DATEDIF(O24,TODAY(),"y") -> 25
A25: =IF(C25=0,"",SUBTOTAL(3,C$5:C25)) -> 21 | B25: 16 | C25: A422 | D25: 9321782052 | E25: Huỳnh Dương Phương Anh | F25: =VLOOKUP(D25,'Sheet1 (2)'!$D$11:$F$338,3,0) -> Huỳnh Dương Phương Anh | G25: 6135000 | I25: Nữ | J25: =IF(I25="nữ",0,1) -> 0 | K25: Kinh | L25: Không | N25: P. KHVT | O25: 37460 | P25: 45748 | Q25: 12 tháng | R25: 20/HĐ-PBHC/2025 | S25: =DATEDIF(P25,TODAY(),"Y") & " NĂM " &DATEDIF(P25,TODAY(),"YM") & " THÁNG " & DATEDIF(P25,TODAY(), "MD") & " NGÀY " -> 1 NĂM 4 THÁNG 18 NGÀY | T25: 093302001656 | U25: 093302001656 | AG25: 45434 | AI25: Cục cảnh sát QLHC về TTXH | AJ25: Xã Long Phú, Thị xã Long Mỹ, Hậu Giang | AK25: Ấp Long Hoà 2, Xã Long Phú, Thị xã Long Mỹ, Hậu Giang | AN25: Đại học | AO25: Kỹ sư KT hoá học | AP25: Do Trưởng phòng phân công công việc | AQ25: =DATEDIF(O25,TODAY(),"y") -> 24
A26: =IF(C26=0,"",SUBTOTAL(3,C$5:C26)) -> 22 | B26: 17 | C26: A424 | D26: 8721741812 | E26: Đặng Thị Uyên Nhi | F26: =VLOOKUP(D26,'Sheet1 (2)'!$D$11:$F$338,3,0) -> Đặng Thị Uyên Nhi | G26: 6135000 | I26: Nữ | J26: =IF(I26="nữ",0,1) -> 0 | K26: Kinh | L26: Không | N26: P. KHVT | O26: 44710 | P26: 45809 | Q26: 12 tháng | R26: 45/HĐ-PBHC/2025 | S26: =DATEDIF(P26,TODAY(),"Y") & " NĂM " &DATEDIF(P26,TODAY(),"YM") & " THÁNG " & DATEDIF(P26,TODAY(), "MD") & " NGÀY " -> 1 NĂM 2 THÁNG 18 NGÀY | T26: 087302004502 | U26: 087302004502 | AG26: 44371 | AI26: Cục cảnh sát QLHC về TTXH | AJ26: Tân Thuận Tây, Tp Cao Lãnh, Đồng Tháp | AK26: 42 tổ 2, ấp Tân Hậu, Tân Thuận Tây, Tp Cao Lãnh | AL26: 42 tổ 2, ấp Tân Hậu, Tân Thuận Tây, Tp Cao Lãnh | AM26: .07036458862 | AN26: Đại học | AO26: Công nghệ Kỹ thuật hóa học | AP26: Do Trưởng phòng phân công công việc | AQ26: =DATEDIF(O26,TODAY(),"y") -> 4
A27: =IF(C27=0,"",SUBTOTAL(3,C$5:C27)) -> 23 | B27: 18 | C27: A429 | D27: 9221356842 | E27: Lê Võ Nhật Khoa | F27: =VLOOKUP(D27,'Sheet1 (2)'!$D$11:$F$338,3,0) -> Lê Võ Nhật Khoa | G27: 6135000 | I27: Nam | K27: Kinh | L27: Không | N27: P. KHVT | O27: 37948 | P27: 45962 | Q27: 12 tháng | R27: 70/HĐ-PBHC/2025 | S27: =DATEDIF(P27,TODAY(),"Y") & " NĂM " &DATEDIF(P27,TODAY(),"YM") & " THÁNG " & DATEDIF(P27,TODAY(), "MD") & " NGÀY " -> 0 NĂM 9 THÁNG 18 NGÀY | T27: 092203005594 | U27: 092203005594 | AG27: 44894 | AI27: Cục cảnh sát QLHC về TTXH | AJ27: Xuân Khánh, Ninh Kiều, Tp Cần Thơ | AK27: 51G5, đường 3/2, Ninh Kiều, Tp Cần Thơ | AL27: 51G5, đường 3/2, Ninh Kiều, Tp Cần Thơ | AM27: 0708119039 | AN27: Đại học | AO27: Truyền thông | AP27: Do Trưởng phòng phân công công việc
A28: =IF(C28=0,"",SUBTOTAL(3,C$5:C28)) -> 24 | B28: 1 | C28: A246 | D28: =VLOOKUP(C28,Sheet4!$A$1:$B$300,2,0) -> 9210002398 | E28: Trần Minh Giàu | F28: =VLOOKUP(D28,'Sheet1 (2)'!$D$11:$F$338,3,0) -> Trần Minh Giàu | G28: =VLOOKUP(C28,'chuyển xếp 2024'!$C$5:$W$328,21,0) -> 7046000 | H28: =VLOOKUP(C28,'chuyển xếp 2024'!$C$5:$W$328,19,0) -> 0 | I28: Nam | J28: =IF(I28="nữ",0,1) -> 1 | K28: Kinh | L28: Không | N28: Phòng TT | O28: 30348 | P28: 40665 | Q28: Không xác định | R28: 23 /HĐ/PBHC/16 | S28: =DATEDIF(P28,TODAY(),"Y") & " NĂM " &DATEDIF(P28,TODAY(),"YM") & " THÁNG " & DATEDIF(P28,TODAY(), "MD") & " NGÀY " -> 15 NĂM 3 THÁNG 17 NGÀY | T28: 092083009975 | U28: =VLOOKUP(C28,Sheet5!$B$2:$G$253,6,0) -> 092083009975 | AI28: Cục cảnh sát QLHC về TTXH | AJ28: Phường An Nghiệp, Quận Ninh Kiều, Thành phố Cần Thơ. | AK28: 112 Trần Hưng Đạo, Quận Ninh Kiều, Thành phố Cần Thơ. | AL28: 138/28 Tràn Hưng Đạo, P. An Nghiệp, Q. Ninh Kiều, TP Cần Thơ | AM28: 0907930044 | AN28: Đại học | AO28: Kỹ sư nông học | AP28: Do Trưởng phòng phân công công việc | AQ28: =DATEDIF(O28,TODAY(),"y") -> 43
A29: =IF(C29=0,"",SUBTOTAL(3,C$5:C29)) -> 25 | B29: 2 | C29: A327 | D29: =VLOOKUP(C29,Sheet4!$A$1:$B$300,2,0) -> 7912294379 | E29: Lê Trung Hiếu | F29: =VLOOKUP(D29,'Sheet1 (2)'!$D$11:$F$338,3,0) -> Lê Trung Hiếu | G29: =VLOOKUP(C29,'chuyển xếp 2024'!$C$5:$W$328,21,0) -> 6647000 | H29: =VLOOKUP(C29,'chuyển xếp 2024'!$C$5:$W$328,19,0) -> 0 | I29: Nam | J29: =IF(I29="nữ",0,1) -> 1 | K29: Kinh | L29: Không | N29: Phòng TT | O29: 32620 | P29: 42370 | Q29: Không xác định | R29: 466 /HĐ/PBHC/16 | S29: =DATEDIF(P29,TODAY(),"Y") & " NĂM " &DATEDIF(P29,TODAY(),"YM") & " THÁNG " & DATEDIF(P29,TODAY(), "MD") & " NGÀY " -> 10 NĂM 7 THÁNG 18 NGÀY | T29: 086089010769 | U29: =VLOOKUP(C29,Sheet5!$B$2:$G$253,6,0) -> 086089010769 | AI29: Cục cảnh sát QLHC về TTXH | AJ29: Xã Trà Côn, Huyện Trà Ôn, Tỉnh Vĩnh Long. | AK29: ấp Ông Tín, Xã Trà Côn, Huyện Trà Ôn, Tỉnh Vĩnh Long. | AL29: 69/62 Hẻm 583 đường 30/4, P. Hưng Lợi, Q. Ninh Kiều, TP Cần Thơ | AM29: 0978618388 | AN29: Cao đẳng | AO29: Công nghệ hóa học | AP29: Do Trưởng phòng phân công công việc | AQ29: =DATEDIF(O29,TODAY(),"y") -> 37
A30: =IF(C30=0,"",SUBTOTAL(3,C$5:C30)) -> 26 | B30: 3 | C30: H062 | D30: =VLOOKUP(C30,Sheet4!$A$1:$B$300,2,0) -> 9213008128 | E30: Lê Bằng Thẳng | F30: =VLOOKUP(D30,'Sheet1 (2)'!$D$11:$F$338,3,0) -> Lê Bằng Thẳng | G30: =VLOOKUP(C30,'chuyển xếp 2024'!$C$5:$W$328,21,0) -> 6647000 | H30: =VLOOKUP(C30,'chuyển xếp 2024'!$C$5:$W$328,19,0) -> 0 | I30: Nam | J30: =IF(I30="nữ",0,1) -> 1 | K30: Kinh | L30: Không | N30: Phòng TT | O30: 31643 | P30: 42156 | Q30: Không xác định | R30: 449 /HĐ/PBHC/16 | S30: =DATEDIF(P30,TODAY(),"Y") & " NĂM " &DATEDIF(P30,TODAY(),"YM") & " THÁNG " & DATEDIF(P30,TODAY(), "MD") & " NGÀY " -> 11 NĂM 2 THÁNG 18 NGÀY | T30: 093086003738 | U30: =VLOOKUP(C30,Sheet5!$B$2:$G$253,6,0) -> 093086003738 | AI30: Cục cảnh sát QLHC về TTXH | AJ30: Phường Trà Lồng, Thị xã Long Mỹ, Tỉnh Hậu Giang. | AK30: KV I, Phường Trà Lồng, Thị xã Long Mỹ, Tỉnh Hậu Giang. | AL30: KV6, Phường Trà Nóc, Q. Bình Thủy, TP Cần Thơ | AN30: Đại học | AO30: Luật | AP30: Do Trưởng phòng phân công công việc | AQ30: =DATEDIF(O30,TODAY(),"y") -> 40
A31: =IF(C31=0,"",SUBTOTAL(3,C$5:C31)) -> 27 | B31: 4 | C31: A328 | D31: =VLOOKUP(C31,Sheet4!$A$1:$B$300,2,0) -> 9216001664 | E31: Huỳnh Phú Nhân | F31: =VLOOKUP(D31,'Sheet1 (2)'!$D$11:$F$338,3,0) -> Huỳnh Phú Nhân | G31: =VLOOKUP(C31,'chuyển xếp 2024'!$C$5:$W$328,21,0) -> 7046000 | H31: =VLOOKUP(C31,'chuyển xếp 2024'!$C$5:$W$328,19,0) -> 0 | I31: Nam | J31: =IF(I31="nữ",0,1) -> 1 | K31: Kinh | L31: Không | N31: Phòng TT | O31: 34633 | P31: 42370 | Q31: Không xác định | R31: 467 /HĐ/PBHC/16 | S31: =DATEDIF(P31,TODAY(),"Y") & " NĂM " &DATEDIF(P31,TODAY(),"YM") & " THÁNG " & DATEDIF(P31,TODAY(), "MD") & " NGÀY " -> 10 NĂM 7 THÁNG 18 NGÀY | T31: 092094005136 | U31: =VLOOKUP(C31,Sheet5!$B$2:$G$253,6,0) -> 092094005136 | AI31: Cục cảnh sát QLHC về TTXH | AJ31: Phường Trường Lạc, Quận Ô Môn, Thành phố Cần Thơ. | AK31: 57 KV Bình Thuận, Phường Trường Lạc, Quận Ô Môn, Thành phố Cần Thơ. | AL31: 57 KV Bình Thuận, Phường Trường Lạc, Quận Ô Môn, Thành phố Cần Thơ. | AN31: Trung cấp | AO31: Bảo vệ thực vật | AP31: Do Trưởng phòng phân công công việc | AQ31: =DATEDIF(O31,TODAY(),"y") -> 31
A32: =IF(C32=0,"",SUBTOTAL(3,C$5:C32)) -> 28 | B32: 5 | C32: A367 | D32: =VLOOKUP(C32,Sheet4!$A$1:$B$300,2,0) -> 9222306746 | E32: Lương Phú Vinh | F32: =VLOOKUP(D32,'Sheet1 (2)'!$D$11:$F$338,3,0) -> Lương Phú Vinh | G32: =VLOOKUP(C32,'chuyển xếp 2024'!$C$5:$W$328,21,0) -> 6647000 | H32: =VLOOKUP(C32,'chuyển xếp 2024'!$C$5:$W$328,19,0) -> 0 | I32: Nam | J32: =IF(I32="nữ",0,1) -> 1 | K32: Kinh | L32: Không | N32: Phòng TT | O32: 33917 | P32: 43405 | Q32: Không xác định | R32: 24 /HĐ-PBHC/18 | S32: =DATEDIF(P32,TODAY(),"Y") & " NĂM " &DATEDIF(P32,TODAY(),"YM") & " THÁNG " & DATEDIF(P32,TODAY(), "MD") & " NGÀY " -> 7 NĂM 9 THÁNG 18 NGÀY | T32: 092092010946 | U32: =VLOOKUP(C32,Sheet5!$B$2:$G$253,6,0) -> 092092010946 | AI32: Cục cảnh sát QLHC về TTXH | AJ32: Xã Trường Long, Huyện Phong Điền, Thành phố Cần Thơ. | AK32: Số 02, ấp Trường Ninh, Xã Trường Long, Huyện Phong Điền, Thành phố Cần Thơ. | AN32: Đại học | AO32: Cử nhân sinh học | AP32: Do giám đốc xí nghiệp Phân bón phân công công việc | AQ32: =DATEDIF(O32,TODAY(),"y") -> 33
A33: =IF(C33=0,"",SUBTOTAL(3,C$5:C33)) -> 29 | B33: 6 | C33: A380 | D33: =VLOOKUP(C33,Sheet4!$A$1:$B$300,2,0) -> 8721755467 | E33: Nguyễn Hoài Phong | F33: =VLOOKUP(D33,'Sheet1 (2)'!$D$11:$F$338,3,0) -> Nguyễn Hoài Phong | G33: =VLOOKUP(C33,'chuyển xếp 2024'!$C$5:$W$328,21,0) -> 6647000 | H33: =VLOOKUP(C33,'chuyển xếp 2024'!$C$5:$W$328,19,0) -> 0 | I33: Nam | J33: =IF(I33="nữ",0,1) -> 1 | K33: Kinh | L33: Không | N33: Phòng TT | O33: 35117 | P33: 44044 | Q33: Không xác định | R33: 14/HĐ-PNHC/2020 | S33: =DATEDIF(P33,TODAY(),"Y") & " NĂM " &DATEDIF(P33,TODAY(),"YM") & " THÁNG " & DATEDIF(P33,TODAY(), "MD") & " NGÀY " -> 6 NĂM 0 THÁNG 18 NGÀY | T33: 341792633 | U33: =VLOOKUP(C33,Sheet5!$B$2:$G$253,6,0) -> 089096016279 | AG33: 40840 | AI33: Cục cảnh sát QLHC về TTXH | AJ33: Xã Hòa An, Tp.Cao Lãnh, Tỉnh Đồng Tháp. | AK33: Số 697, Nguyễn Hữu Kiến, Ấp Hòa Long, Xã Hòa An, Tp.Cao Lãnh, Tỉnh Đồng Tháp. | AL33: Hẻm 1, KV1 Trần Vĩnh Kiết, P.An Bình, TP Cần Thơ | AN33: Đại học | AO33: Phát triển nông thôn | AP33: Do Trưởng phòng phân công công việc | AQ33: =DATEDIF(O33,TODAY(),"y") -> 30
A34: =IF(C34=0,"",SUBTOTAL(3,C$5:C34)) -> 30 | B34: 7 | C34: A344 | D34: =VLOOKUP(C34,Sheet4!$A$1:$B$300,2,0) -> 9216023766 | E34: Lê Trọng Nhơn | F34: =VLOOKUP(D34,'Sheet1 (2)'!$D$11:$F$338,3,0) -> Lê Trọng Nhơn | G34: =VLOOKUP(C34,'chuyển xếp 2024'!$C$5:$W$328,17,0) -> 7105000 | H34: 2205000 | I34: Nam | J34: =IF(I34="nữ",0,1) -> 1 | K34: Kinh | L34: Không | M34: Phụ trách phòng | N34: Phòng TT | O34: 33633 | P34: 42736 | Q34: Không xác định | R34: 05 /HĐ/PBHC/17 | S34: =DATEDIF(P34,TODAY(),"Y") & " NĂM " &DATEDIF(P34,TODAY(),"YM") & " THÁNG " & DATEDIF(P34,TODAY(), "MD") & " NGÀY " -> 9 NĂM 7 THÁNG 18 NGÀY | T34: 087092017349 | U34: =VLOOKUP(C34,Sheet5!$B$2:$G$253,6,0) -> 087092017349 | AI34: Cục cảnh sát QLHC về TTXH | AJ34: Xã Vĩnh Thới, Huyện Lai Vung, Tỉnh Đồng Tháp. | AK34: 1312 ấp Hòa Định, Xã Vĩnh Thới, Huyện Lai Vung, Tỉnh Đồng Tháp. | AL34: 1312 ấp Hòa Định, Xã Vĩnh Thới, Huyện Lai Vung, Tỉnh Đồng Tháp. | AM34: 0981205448 | AN34: Đại học | AO34: Công nghệ hóa học | AP34: Do Trưởng phòng phân công công việc | AQ34: =DATEDIF(O34,TODAY(),"y") -> 34
A35: =IF(C35=0,"",SUBTOTAL(3,C$5:C35)) -> 31 | B35: 8 | C35: A394 | D35: =VLOOKUP(C35,Sheet4!$A$1:$B$300,2,0) -> 9222451383 | E35: Nguyễn Hứa Kim Thảo | F35: =VLOOKUP(D35,'Sheet1 (2)'!$D$11:$F$338,3,0) -> Nguyễn Hứa Kim Thảo | G35: =VLOOKUP(C35,'chuyển xếp 2024'!$C$5:$W$328,21,0) -> 5466000 | H35: =VLOOKUP(C35,'chuyển xếp 2024'!$C$5:$W$328,19,0) -> 0 | I35: Nữ | J35: =IF(I35="nữ",0,1) -> 0 | K35: Kinh | L35: Không | N35: Phòng TT | O35: 35524 | P35: 44805 | Q35: Không xác định | R35: 29/HĐ-PBHC/2022 | S35: =DATEDIF(P35,TODAY(),"Y") & " NĂM " &DATEDIF(P35,TODAY(),"YM") & " THÁNG " & DATEDIF(P35,TODAY(), "MD") & " NGÀY " -> 3 NĂM 11 THÁNG 18 NGÀY | T35: 092197011285 | U35: =VLOOKUP(C35,Sheet5!$B$2:$G$253,6,0) -> 092197011285 | AG35: 44440 | AI35: Cục cảnh sát QLHC về TTXH | AJ35: H. Thới Lai, TP. Cần Thơ | AK35: 66/1 Huỳnh Phan Hộ, P. Trà An, Q. Bình Thủy, TP. Cần Thơ | AL35: 66/1 Huỳnh Phan Hộ, P. Trà An, Q. Bình Thủy, TP. Cần Thơ | AM35: 0907 199 744 | AN35: Cao Đẳng | AO35: Quản trị văn phòng | AP35: Do Trưởng phòng phân công công việc | AQ35: =DATEDIF(O35,TODAY(),"y") -> 29
A36: =IF(C36=0,"",SUBTOTAL(3,C$5:C36)) -> 32 | B36: 9 | C36: A397 | D36: =VLOOKUP(C36,Sheet4!$A$1:$B$300,2,0) -> 9208016265 | E36: Mạch Chí Thiện | F36: =VLOOKUP(D36,'Sheet1 (2)'!$D$11:$F$338,3,0) -> Mạch Chí Thiện | G36: =VLOOKUP(C36,'chuyển xếp 2024'!$C$5:$W$328,21,0) -> #N/A | H36: =VLOOKUP(C36,'chuyển xếp 2024'!$C$5:$W$328,19,0) -> #N/A | I36: Nam | J36: =IF(I36="nữ",0,1) -> 1 | K36: Kinh | L36: Không | N36: Phòng TT | O36: 30482 | P36: 44866 | Q36: Không xác định | R36: 33/HĐ-PBHC/2022 | S36: =DATEDIF(P36,TODAY(),"Y") & " NĂM " &DATEDIF(P36,TODAY(),"YM") & " THÁNG " & DATEDIF(P36,TODAY(), "MD") & " NGÀY " -> 3 NĂM 9 THÁNG 18 NGÀY | T36: 086083000292 | U36: =VLOOKUP(C36,Sheet5!$B$2:$G$253,6,0) -> 086083000292 | AG36: 44326 | AI36: Cục cảnh sát QLHC về TTXH | AJ36: Xã Trung Hiệp, H. Vũng Liêm, T. Vĩnh Long | AK36: KV Tân Quới, P. Tân Hưng, Q.Thốt Nốt, TP. Cần Thơ | AL36: KV Tân Quới, P. Tân Hưng, Q.Thốt Nốt, TP. Cần Thơ | AN36: Đại học | AO36: Công nghệ hóa học | AP36: Do Trưởng phòng phân công công việc | AQ36: =DATEDIF(O36,TODAY(),"y") -> 43
A37: =IF(C37=0,"",SUBTOTAL(3,C$5:C37)) -> 33 | B37: 10 | C37: A403 | D37: =VLOOKUP(C37,Sheet4!$A$1:$B$300,2,0) -> 8922957383 | E37: Ngô Văn Tài | F37: =VLOOKUP(D37,'Sheet1 (2)'!$D$11:$F$338,3,0) -> Ngô Văn Tài | G37: =VLOOKUP(C37,'chuyển xếp 2024'!$C$5:$W$328,21,0) -> 6271000 | H37: =VLOOKUP(C37,'chuyển xếp 2024'!$C$5:$W$328,19,0) -> 0 | I37: Nam | J37: =IF(I37="nữ",0,1) -> 1 | K37: Kinh | L37: Không | N37: Phòng TT | O37: 35231 | P37: 45113 | Q37: Không xác định | R37: 24/HĐ-PBHC/2023 | S37: =DATEDIF(P37,TODAY(),"Y") & " NĂM " &DATEDIF(P37,TODAY(),"YM") & " THÁNG " & DATEDIF(P37,TODAY(), "MD") & " NGÀY " -> 3 NĂM 1 THÁNG 13 NGÀY | T37: 089096013188 | U37: 089096013188 | AG37: 44421 | AI37: Cục cảnh sát QLHC về TTXH | AJ37: Phú mỹ Hạ, Phú Thọ, Phú Tân, An Giang | AK37: Phú mỹ Hạ, Phú Thọ, Phú Tân, An Giang | AL37: Phú mỹ Hạ, Phú Thọ, Phú Tân, An Giang | AN37: Đại học | AP37: Do Trưởng phòng phân công công việc | AQ37: =DATEDIF(O37,TODAY(),"y") -> 30
A38: =IF(C38=0,"",SUBTOTAL(3,C$5:C38)) -> 34 | B38: 12 | C38: A283 | D38: =VLOOKUP(C38,Sheet4!$A$1:$B$300,2,0) -> 9214000894 | E38: Cao Văn Được | F38: =VLOOKUP(D38,'Sheet1 (2)'!$D$11:$F$338,3,0) -> Cao Văn Được | G38: =VLOOKUP(C38,'chuyển xếp 2024'!$C$5:$W$328,21,0) -> 6785000 | H38: =VLOOKUP(C38,'chuyển xếp 2024'!$C$5:$W$328,19,0) -> 0 | I38: Nam | J38: =IF(I38="nữ",0,1) -> 1 | K38: Kinh | L38: Không | N38: Phòng TT | O38: 32488 | P38: 41641 | Q38: Không xác định | R38: 65 /HĐ/PBHC/16 | S38: =DATEDIF(P38,TODAY(),"Y") & " NĂM " &DATEDIF(P38,TODAY(),"YM") & " THÁNG " & DATEDIF(P38,TODAY(), "MD") & " NGÀY " -> 12 NĂM 7 THÁNG 17 NGÀY | T38: 092088000675 | U38: =VLOOKUP(C38,Sheet5!$B$2:$G$253,6,0) -> 092088000675 | AG38: 42299 | AI38: Cục cảnh sát QLHC về TTXH | AJ38: Xã Thạnh Phú, Huyện Vĩnh Thạnh, TP.Cần Thơ. | AK38: KV Thới Mỹ, Phường Thới Long, Quận Ô Môn, Thành phố Cần Thơ. | AL38: 180 Nguyễn Đệ, P. An Thới, Q. Bình Thủy, TP Cần Thơ | AN38: Đại học | AO38: KT Ngoại Thương | AP38: Do Trưởng bộ phận phân công công việc | AQ38: =DATEDIF(O38,TODAY(),"y") -> 37
A39: =IF(C39=0,"",SUBTOTAL(3,C$5:C39)) -> 35 | B39: 13 | C39: A418 | D39: 8913009900 | E39: Lê Thanh Đạm | F39: =VLOOKUP(D39,'Sheet1 (2)'!$D$11:$F$338,3,0) -> Lê Thanh Đạm | G39: 5955000 | I39: Nam | J39: =IF(I39="nữ",0,1) -> 1 | K39: Kinh | L39: Không | N39: Phòng TT | O39: 31692 | P39: 45627 | Q39: 12 tháng | R39: 56//HĐ-PBHC/2024 | S39: =DATEDIF(P39,TODAY(),"Y") & " NĂM " &DATEDIF(P39,TODAY(),"YM") & " THÁNG " & DATEDIF(P39,TODAY(), "MD") & " NGÀY " -> 1 NĂM 8 THÁNG 18 NGÀY | T39: 089086005984 | U39: 089086005984 | AG39: 44205 | AI39: Cục cảnh sát QLHC về TTXH | AJ39: Kiến An- Chợ Mới- An Giang | AK39: Ấp Hòa Hạ-Kiến An- Chợ Mới- An Giang | AL39: Kiến An- Chợ Mới- An Giang | AM39: 0353857516 | AN39: Đại học | AO39: Phát triển nông thôn | AP39: Do Trưởng phòng phân công công việc | AQ39: =DATEDIF(O39,TODAY(),"y") -> 39
A40: =IF(C40=0,"",SUBTOTAL(3,C$5:C40)) -> 36 | B40: 14 | C40: A420 | D40: 9622993923 | E40: Nguyễn Kiều Ly | F40: =VLOOKUP(D40,'Sheet1 (2)'!$D$11:$F$338,3,0) -> Nguyễn Kiều Ly | G40: 6135000 | I40: Nữ | J40: =IF(I40="nữ",0,1) -> 0 | K40: Kinh | L40: Không | N40: Phòng TT | O40: 35107 | P40: 45717 | Q40: 12 tháng | R40: 02/HĐ-PBHC/2025 | S40: =DATEDIF(P40,TODAY(),"Y") & " NĂM " &DATEDIF(P40,TODAY(),"YM") & " THÁNG " & DATEDIF(P40,TODAY(), "MD") & " NGÀY " -> 1 NĂM 5 THÁNG 18 NGÀY | T40: 096196008540 | U40: 096196008540 | AG40: 44853 | AI40: Cục cảnh sát QLHC về TTXH | AJ40: Xã Hoà Tân, Tp Cà Mau, tỉnh Cà Mau | AK40: 79, KV Bình Thuận, Trường Lạc, Ô Môn, Tp Cần Thơ | AL40: 79, KV Bình Thuận, Trường Lạc, Ô Môn, Tp Cần Thơ | AM40: 944194914 | AN40: Đại học | AO40: Quản lý đất đai | AP40: Do Trưởng phòng phân công công việc
A41: =IF(C41=0,"",SUBTOTAL(3,C$5:C41)) -> 37 | B41: 1 | C41: A198 | D41: =VLOOKUP(C41,Sheet4!$A$1:$B$300,2,0) -> 5803003379 | E41: Nguyễn Duy Vũ | F41: =VLOOKUP(D41,'Sheet1 (2)'!$D$11:$F$338,3,0) -> Nguyễn Duy Vũ | G41: =VLOOKUP(C41,'chuyển xếp 2024'!$C$5:$W$328,21,0) -> 19950000 | H41: =VLOOKUP(C41,'chuyển xếp 2024'!$C$5:$W$328,19,0) -> 0 | I41: Nam | J41: =IF(I41="nữ",0,1) -> 1 | K41: Kinh | L41: Không | M41: Kế toán trưởng | N41: Phòng KTTC | O41: 28767 | P41: 39265 | Q41: Không xác định | R41: 42 /HĐ/PBHC/16 | S41: =DATEDIF(P41,TODAY(),"Y") & " NĂM " &DATEDIF(P41,TODAY(),"YM") & " THÁNG " & DATEDIF(P41,TODAY(), "MD") & " NGÀY " -> 19 NĂM 1 THÁNG 17 NGÀY | T41: 082078026532 | U41: =VLOOKUP(C41,Sheet5!$B$2:$G$253,6,0) -> 082078026532 | AI41: Cục cảnh sát QLHC về TTXH | AJ41: Xã Long Hòa, Thị xã Gò Công, Tỉnh Tiền Giang. | AK41: 9113 Ấp Kim Liên, Xã Long Hòa, Thị xã Gò Công, Tỉnh Tiền Giang. | AL41: Đường số 32 KDC Ngân Thuận, P. Bình Thủy, Q. Bình Thủy, TP Cần Thơ | AN41: Đại học | AO41: QTKD | AP41: Do Trưởng phòng phân công công việc | AQ41: =DATEDIF(O41,TODAY(),"y") -> 47
...

Sheet T2-26
B1: DANH SÁCH NHÂN SỰ | R1: Ngày làm | S1: Năm công tác | T1: Ngày tính
B2: XÍ NGHIỆP PHÂN BÓN HÓA CHẤT | R2: 37087 | S2: =DATEDIF(R2,T2,"Y") & " NĂM " &DATEDIF(R2,T2,"YM") & " THÁNG " & DATEDIF(R2,T2, "MD") & " NGÀY " -> 7 NĂM 5 THÁNG 16 NGÀY | T2: 39813
A4: STT | B4: STT | C4: MÃ SỐ | E4: HỌ VÀ TÊN | G4: Lương | H4: Phụ cấp | I4: GIỚI TÍNH | K4: DÂN TỘC | L4: TÔN GIÁO | M4: CHỨC VỤ | N4: ĐƠN VỊ CÔNG TÁC | O4: NGÀY SINH | P4: NGÀY LÀM | Q4: HĐLĐ | R4: SỐ HĐLĐ | S4: NĂM CÔNG TÁC | T4: CMND | U4: CCCD | V4: Quốc tịch | W4: Nâng Lương | X4: Số ngày nghỉ trong năm | Y4: Số giờ làm thêm | Z4: Đào tạo bồi dưỡng chuyên môn KT | AA4: Kỷ luật lao động | AB4: Trách nhiệm vật chất | AC4: Tai nạn lao động | AD4: Bệnh nghề nghiệp | AE4: Thời điểm chấm dứt HĐLĐ | AF4: Lý do | AG4: NGÀY CẤP | AI4: NƠI CẤP | AJ4: NƠI SINH | AK4: ĐỊA CHỈ THƯỜNG TRÚ | AL4: ĐỊA CHỈ HIỆN NAY | AM4: SỐ ĐIỆN THOẠI | AN4: TRÌNH ĐỘ | AO4: CHUYÊN NGÀNH | AP4: CÔNG VIỆC PHẢI LÀM | AQ4: Tuổi
